[2024-07-01T20:32:26.102-0400] {local_task_job_runner.py:120} INFO - ::group::Pre task execution logs
[2024-07-01T20:32:26.116-0400] {taskinstance.py:2076} INFO - Dependencies all met for dep_context=non-requeueable deps ti=<TaskInstance: api_cuevana3_movie.execute_post_details_fasapi scheduled__2024-07-01T15:00:00+00:00 [queued]>
[2024-07-01T20:32:26.124-0400] {taskinstance.py:2076} INFO - Dependencies all met for dep_context=requeueable deps ti=<TaskInstance: api_cuevana3_movie.execute_post_details_fasapi scheduled__2024-07-01T15:00:00+00:00 [queued]>
[2024-07-01T20:32:26.125-0400] {taskinstance.py:2306} INFO - Starting attempt 1 of 1
[2024-07-01T20:32:26.163-0400] {taskinstance.py:2330} INFO - Executing <Task(PythonOperator): execute_post_details_fasapi> on 2024-07-01 15:00:00+00:00
[2024-07-01T20:32:26.169-0400] {standard_task_runner.py:63} INFO - Started process 417558 to run task
[2024-07-01T20:32:26.172-0400] {standard_task_runner.py:90} INFO - Running: ['airflow', 'tasks', 'run', 'api_cuevana3_movie', 'execute_post_details_fasapi', 'scheduled__2024-07-01T15:00:00+00:00', '--job-id', '734', '--raw', '--subdir', 'DAGS_FOLDER/movie_recommend.py', '--cfg-path', '/tmp/tmpzh4k35yx']
[2024-07-01T20:32:26.173-0400] {standard_task_runner.py:91} INFO - Job 734: Subtask execute_post_details_fasapi
[2024-07-01T20:32:26.227-0400] {task_command.py:426} INFO - Running <TaskInstance: api_cuevana3_movie.execute_post_details_fasapi scheduled__2024-07-01T15:00:00+00:00 [running]> on host walter-VirtualBox
[2024-07-01T20:32:26.301-0400] {taskinstance.py:2648} INFO - Exporting env vars: AIRFLOW_CTX_DAG_OWNER='airflow' AIRFLOW_CTX_DAG_ID='api_cuevana3_movie' AIRFLOW_CTX_TASK_ID='execute_post_details_fasapi' AIRFLOW_CTX_EXECUTION_DATE='2024-07-01T15:00:00+00:00' AIRFLOW_CTX_TRY_NUMBER='1' AIRFLOW_CTX_DAG_RUN_ID='scheduled__2024-07-01T15:00:00+00:00'
[2024-07-01T20:32:26.302-0400] {taskinstance.py:430} INFO - ::endgroup::
[2024-07-01T20:32:26.334-0400] {taskinstance.py:441} INFO - ::group::Post task execution logs
[2024-07-01T20:32:26.335-0400] {taskinstance.py:2905} ERROR - Task failed with exception
Traceback (most recent call last):
  File "/home/walter/Documentos/rakuntentv/venv/lib/python3.12/site-packages/urllib3/connection.py", line 196, in _new_conn
    sock = connection.create_connection(
           ^^^^^^^^^^^^^^^^^^^^^^^^^^^^^
  File "/home/walter/Documentos/rakuntentv/venv/lib/python3.12/site-packages/urllib3/util/connection.py", line 85, in create_connection
    raise err
  File "/home/walter/Documentos/rakuntentv/venv/lib/python3.12/site-packages/urllib3/util/connection.py", line 73, in create_connection
    sock.connect(sa)
ConnectionRefusedError: [Errno 111] Connection refused

The above exception was the direct cause of the following exception:

Traceback (most recent call last):
  File "/home/walter/Documentos/rakuntentv/venv/lib/python3.12/site-packages/urllib3/connectionpool.py", line 789, in urlopen
    response = self._make_request(
               ^^^^^^^^^^^^^^^^^^^
  File "/home/walter/Documentos/rakuntentv/venv/lib/python3.12/site-packages/urllib3/connectionpool.py", line 495, in _make_request
    conn.request(
  File "/home/walter/Documentos/rakuntentv/venv/lib/python3.12/site-packages/urllib3/connection.py", line 398, in request
    self.endheaders()
  File "/usr/lib/python3.12/http/client.py", line 1331, in endheaders
    self._send_output(message_body, encode_chunked=encode_chunked)
  File "/usr/lib/python3.12/http/client.py", line 1091, in _send_output
    self.send(msg)
  File "/usr/lib/python3.12/http/client.py", line 1035, in send
    self.connect()
  File "/home/walter/Documentos/rakuntentv/venv/lib/python3.12/site-packages/urllib3/connection.py", line 236, in connect
    self.sock = self._new_conn()
                ^^^^^^^^^^^^^^^^
  File "/home/walter/Documentos/rakuntentv/venv/lib/python3.12/site-packages/urllib3/connection.py", line 211, in _new_conn
    raise NewConnectionError(
urllib3.exceptions.NewConnectionError: <urllib3.connection.HTTPConnection object at 0x6fff1d822570>: Failed to establish a new connection: [Errno 111] Connection refused

The above exception was the direct cause of the following exception:

Traceback (most recent call last):
  File "/home/walter/Documentos/rakuntentv/venv/lib/python3.12/site-packages/requests/adapters.py", line 667, in send
    resp = conn.urlopen(
           ^^^^^^^^^^^^^
  File "/home/walter/Documentos/rakuntentv/venv/lib/python3.12/site-packages/urllib3/connectionpool.py", line 843, in urlopen
    retries = retries.increment(
              ^^^^^^^^^^^^^^^^^^
  File "/home/walter/Documentos/rakuntentv/venv/lib/python3.12/site-packages/urllib3/util/retry.py", line 519, in increment
    raise MaxRetryError(_pool, url, reason) from reason  # type: ignore[arg-type]
    ^^^^^^^^^^^^^^^^^^^^^^^^^^^^^^^^^^^^^^^^^^^^^^^^^^^
urllib3.exceptions.MaxRetryError: HTTPConnectionPool(host='localhost', port=8000): Max retries exceeded with url: /scraper-movies-details (Caused by NewConnectionError('<urllib3.connection.HTTPConnection object at 0x6fff1d822570>: Failed to establish a new connection: [Errno 111] Connection refused'))

During handling of the above exception, another exception occurred:

Traceback (most recent call last):
  File "/home/walter/Documentos/rakuntentv/venv/lib/python3.12/site-packages/airflow/models/taskinstance.py", line 465, in _execute_task
    result = _execute_callable(context=context, **execute_callable_kwargs)
             ^^^^^^^^^^^^^^^^^^^^^^^^^^^^^^^^^^^^^^^^^^^^^^^^^^^^^^^^^^^^^
  File "/home/walter/Documentos/rakuntentv/venv/lib/python3.12/site-packages/airflow/models/taskinstance.py", line 432, in _execute_callable
    return execute_callable(context=context, **execute_callable_kwargs)
           ^^^^^^^^^^^^^^^^^^^^^^^^^^^^^^^^^^^^^^^^^^^^^^^^^^^^^^^^^^^^
  File "/home/walter/Documentos/rakuntentv/venv/lib/python3.12/site-packages/airflow/models/baseoperator.py", line 401, in wrapper
    return func(self, *args, **kwargs)
           ^^^^^^^^^^^^^^^^^^^^^^^^^^^
  File "/home/walter/Documentos/rakuntentv/venv/lib/python3.12/site-packages/airflow/operators/python.py", line 235, in execute
    return_value = self.execute_callable()
                   ^^^^^^^^^^^^^^^^^^^^^^^
  File "/home/walter/Documentos/rakuntentv/venv/lib/python3.12/site-packages/airflow/operators/python.py", line 252, in execute_callable
    return self.python_callable(*self.op_args, **self.op_kwargs)
           ^^^^^^^^^^^^^^^^^^^^^^^^^^^^^^^^^^^^^^^^^^^^^^^^^^^^^
  File "/home/walter/Documentos/rakuntentv/airflow/dags/movie_recommend.py", line 60, in execute_post_details_fasapi
    response = requests.post(api_url)
               ^^^^^^^^^^^^^^^^^^^^^^
  File "/home/walter/Documentos/rakuntentv/venv/lib/python3.12/site-packages/requests/api.py", line 115, in post
    return request("post", url, data=data, json=json, **kwargs)
           ^^^^^^^^^^^^^^^^^^^^^^^^^^^^^^^^^^^^^^^^^^^^^^^^^^^^
  File "/home/walter/Documentos/rakuntentv/venv/lib/python3.12/site-packages/requests/api.py", line 59, in request
    return session.request(method=method, url=url, **kwargs)
           ^^^^^^^^^^^^^^^^^^^^^^^^^^^^^^^^^^^^^^^^^^^^^^^^^
  File "/home/walter/Documentos/rakuntentv/venv/lib/python3.12/site-packages/requests/sessions.py", line 589, in request
    resp = self.send(prep, **send_kwargs)
           ^^^^^^^^^^^^^^^^^^^^^^^^^^^^^^
  File "/home/walter/Documentos/rakuntentv/venv/lib/python3.12/site-packages/requests/sessions.py", line 703, in send
    r = adapter.send(request, **kwargs)
        ^^^^^^^^^^^^^^^^^^^^^^^^^^^^^^^
  File "/home/walter/Documentos/rakuntentv/venv/lib/python3.12/site-packages/requests/adapters.py", line 700, in send
    raise ConnectionError(e, request=request)
requests.exceptions.ConnectionError: HTTPConnectionPool(host='localhost', port=8000): Max retries exceeded with url: /scraper-movies-details (Caused by NewConnectionError('<urllib3.connection.HTTPConnection object at 0x6fff1d822570>: Failed to establish a new connection: [Errno 111] Connection refused'))
[2024-07-01T20:32:26.345-0400] {taskinstance.py:1206} INFO - Marking task as FAILED. dag_id=api_cuevana3_movie, task_id=execute_post_details_fasapi, run_id=scheduled__2024-07-01T15:00:00+00:00, execution_date=20240701T150000, start_date=20240702T003226, end_date=20240702T003226
[2024-07-01T20:32:26.369-0400] {standard_task_runner.py:110} ERROR - Failed to execute job 734 for task execute_post_details_fasapi (HTTPConnectionPool(host='localhost', port=8000): Max retries exceeded with url: /scraper-movies-details (Caused by NewConnectionError('<urllib3.connection.HTTPConnection object at 0x6fff1d822570>: Failed to establish a new connection: [Errno 111] Connection refused')); 417558)
[2024-07-01T20:32:26.396-0400] {local_task_job_runner.py:240} INFO - Task exited with return code 1
[2024-07-01T20:32:26.431-0400] {taskinstance.py:3503} INFO - 0 downstream tasks scheduled from follow-on schedule check
[2024-07-01T20:32:26.458-0400] {local_task_job_runner.py:222} INFO - ::endgroup::
[2024-07-01T23:22:14.688-0400] {local_task_job_runner.py:120} INFO - ::group::Pre task execution logs
[2024-07-01T23:22:14.710-0400] {taskinstance.py:2076} INFO - Dependencies all met for dep_context=non-requeueable deps ti=<TaskInstance: api_cuevana3_movie.execute_post_details_fasapi scheduled__2024-07-01T15:00:00+00:00 [queued]>
[2024-07-01T23:22:14.714-0400] {taskinstance.py:2076} INFO - Dependencies all met for dep_context=requeueable deps ti=<TaskInstance: api_cuevana3_movie.execute_post_details_fasapi scheduled__2024-07-01T15:00:00+00:00 [queued]>
[2024-07-01T23:22:14.715-0400] {taskinstance.py:2306} INFO - Starting attempt 1 of 1
[2024-07-01T23:22:14.732-0400] {taskinstance.py:2330} INFO - Executing <Task(PythonOperator): execute_post_details_fasapi> on 2024-07-01 15:00:00+00:00
[2024-07-01T23:22:14.738-0400] {standard_task_runner.py:63} INFO - Started process 452095 to run task
[2024-07-01T23:22:14.741-0400] {standard_task_runner.py:90} INFO - Running: ['airflow', 'tasks', 'run', 'api_cuevana3_movie', 'execute_post_details_fasapi', 'scheduled__2024-07-01T15:00:00+00:00', '--job-id', '877', '--raw', '--subdir', 'DAGS_FOLDER/movie_recommend.py', '--cfg-path', '/tmp/tmpn_pg0g7x']
[2024-07-01T23:22:14.744-0400] {standard_task_runner.py:91} INFO - Job 877: Subtask execute_post_details_fasapi
[2024-07-01T23:22:14.790-0400] {task_command.py:426} INFO - Running <TaskInstance: api_cuevana3_movie.execute_post_details_fasapi scheduled__2024-07-01T15:00:00+00:00 [running]> on host walter-VirtualBox
[2024-07-01T23:22:14.863-0400] {taskinstance.py:2648} INFO - Exporting env vars: AIRFLOW_CTX_DAG_OWNER='airflow' AIRFLOW_CTX_DAG_ID='api_cuevana3_movie' AIRFLOW_CTX_TASK_ID='execute_post_details_fasapi' AIRFLOW_CTX_EXECUTION_DATE='2024-07-01T15:00:00+00:00' AIRFLOW_CTX_TRY_NUMBER='1' AIRFLOW_CTX_DAG_RUN_ID='scheduled__2024-07-01T15:00:00+00:00'
[2024-07-01T23:22:14.867-0400] {taskinstance.py:430} INFO - ::endgroup::
[2024-07-01T23:23:08.879-0400] {logging_mixin.py:188} INFO - Scraping movie details running successfully
[2024-07-01T23:23:08.929-0400] {logging_mixin.py:188} INFO - {"image_url": "https://i0.wp.com/www.themoviedb.org/t/p/w185/5jI2vEHJReAx8iFDmhC2O3yW37w.jpg", "title": "Bad Boys: Ride or Die", "rating": 6.9, "duration": "1h 55m", "year": "2024", "quality": "HD", "description": "Ver bad boys: ride or die Cuevana3.Tras escuchar falsas acusaciones sobre su excapit\u00e1n y mentor Mike y Marcus deciden investigar el asunto incluso volverse los m\u00e1s buscados de ser necesarios", "genre": ["Acci\u00f3n", "Crimen", "Suspense", "Comedia"], "country": "United States", "director": "Adil El Arbi", "actors": ["Will Smith,", "Martin Lawrence,", "Vanessa Hudgens,", "Alexander Ludwig,", "Paola Nu\u00f1ez,", "Eric Dane,", "Ioan Gruffudd,", "Jacob Scipio,", "Melanie Liburd,", "Tasha Smith,", "Rhea Seehorn,", "Tiffany Haddish,", "Joe Pantoliano,", "DJ Khaled,", "John Salley,", "Bianca Bethune,", "Dennis McDonald,", "Quinn Hemphill,", "Michael Bay,", "Derek Russo,", "Karter Reese Newsome,"], "views": 460}
[2024-07-01T23:23:08.960-0400] {python.py:237} INFO - Done. Returned value was: {"image_url": "https://i0.wp.com/www.themoviedb.org/t/p/w185/5jI2vEHJReAx8iFDmhC2O3yW37w.jpg", "title": "Bad Boys: Ride or Die", "rating": 6.9, "duration": "1h 55m", "year": "2024", "quality": "HD", "description": "Ver bad boys: ride or die Cuevana3.Tras escuchar falsas acusaciones sobre su excapit\u00e1n y mentor Mike y Marcus deciden investigar el asunto incluso volverse los m\u00e1s buscados de ser necesarios", "genre": ["Acci\u00f3n", "Crimen", "Suspense", "Comedia"], "country": "United States", "director": "Adil El Arbi", "actors": ["Will Smith,", "Martin Lawrence,", "Vanessa Hudgens,", "Alexander Ludwig,", "Paola Nu\u00f1ez,", "Eric Dane,", "Ioan Gruffudd,", "Jacob Scipio,", "Melanie Liburd,", "Tasha Smith,", "Rhea Seehorn,", "Tiffany Haddish,", "Joe Pantoliano,", "DJ Khaled,", "John Salley,", "Bianca Bethune,", "Dennis McDonald,", "Quinn Hemphill,", "Michael Bay,", "Derek Russo,", "Karter Reese Newsome,"], "views": 460}
[2024-07-01T23:23:08.960-0400] {taskinstance.py:441} INFO - ::group::Post task execution logs
[2024-07-01T23:23:08.994-0400] {taskinstance.py:1206} INFO - Marking task as SUCCESS. dag_id=api_cuevana3_movie, task_id=execute_post_details_fasapi, run_id=scheduled__2024-07-01T15:00:00+00:00, execution_date=20240701T150000, start_date=20240702T032214, end_date=20240702T032308
[2024-07-01T23:23:09.040-0400] {local_task_job_runner.py:240} INFO - Task exited with return code 0
[2024-07-01T23:23:09.071-0400] {taskinstance.py:3503} INFO - 0 downstream tasks scheduled from follow-on schedule check
[2024-07-01T23:23:09.072-0400] {local_task_job_runner.py:222} INFO - ::endgroup::
