[2024-07-02T09:39:31.054-0400] {local_task_job_runner.py:120} INFO - ::group::Pre task execution logs
[2024-07-02T09:39:31.084-0400] {taskinstance.py:2076} INFO - Dependencies all met for dep_context=non-requeueable deps ti=<TaskInstance: api_cuevana3_movie.execute_post_url_fastapi scheduled__2024-07-01T00:01:15+00:00 [queued]>
[2024-07-02T09:39:31.090-0400] {taskinstance.py:2076} INFO - Dependencies all met for dep_context=requeueable deps ti=<TaskInstance: api_cuevana3_movie.execute_post_url_fastapi scheduled__2024-07-01T00:01:15+00:00 [queued]>
[2024-07-02T09:39:31.090-0400] {taskinstance.py:2306} INFO - Starting attempt 1 of 1
[2024-07-02T09:39:31.126-0400] {taskinstance.py:2330} INFO - Executing <Task(PythonOperator): execute_post_url_fastapi> on 2024-07-01 00:01:15+00:00
[2024-07-02T09:39:31.140-0400] {standard_task_runner.py:63} INFO - Started process 482588 to run task
[2024-07-02T09:39:31.148-0400] {standard_task_runner.py:90} INFO - Running: ['airflow', 'tasks', 'run', 'api_cuevana3_movie', 'execute_post_url_fastapi', 'scheduled__2024-07-01T00:01:15+00:00', '--job-id', '965', '--raw', '--subdir', 'DAGS_FOLDER/movie_recommend.py', '--cfg-path', '/tmp/tmplh7fhl8v']
[2024-07-02T09:39:31.151-0400] {standard_task_runner.py:91} INFO - Job 965: Subtask execute_post_url_fastapi
[2024-07-02T09:39:31.265-0400] {task_command.py:426} INFO - Running <TaskInstance: api_cuevana3_movie.execute_post_url_fastapi scheduled__2024-07-01T00:01:15+00:00 [running]> on host walter-VirtualBox
[2024-07-02T09:39:31.425-0400] {taskinstance.py:2648} INFO - Exporting env vars: AIRFLOW_CTX_DAG_OWNER='airflow' AIRFLOW_CTX_DAG_ID='api_cuevana3_movie' AIRFLOW_CTX_TASK_ID='execute_post_url_fastapi' AIRFLOW_CTX_EXECUTION_DATE='2024-07-01T00:01:15+00:00' AIRFLOW_CTX_TRY_NUMBER='1' AIRFLOW_CTX_DAG_RUN_ID='scheduled__2024-07-01T00:01:15+00:00'
[2024-07-02T09:39:31.425-0400] {taskinstance.py:430} INFO - ::endgroup::
[2024-07-02T09:39:33.427-0400] {logging_mixin.py:188} INFO - Scraping URL did not find any new URLs
[2024-07-02T09:39:33.432-0400] {python.py:237} INFO - Done. Returned value was: None
[2024-07-02T09:39:33.433-0400] {taskinstance.py:441} INFO - ::group::Post task execution logs
[2024-07-02T09:39:33.446-0400] {taskinstance.py:1206} INFO - Marking task as SUCCESS. dag_id=api_cuevana3_movie, task_id=execute_post_url_fastapi, run_id=scheduled__2024-07-01T00:01:15+00:00, execution_date=20240701T000115, start_date=20240702T133931, end_date=20240702T133933
[2024-07-02T09:39:33.547-0400] {local_task_job_runner.py:240} INFO - Task exited with return code 0
[2024-07-02T09:39:33.579-0400] {taskinstance.py:3503} INFO - 3 downstream tasks scheduled from follow-on schedule check
[2024-07-02T09:39:33.587-0400] {local_task_job_runner.py:222} INFO - ::endgroup::
[2024-07-02T10:20:24.087-0400] {local_task_job_runner.py:120} INFO - ::group::Pre task execution logs
[2024-07-02T10:20:24.110-0400] {taskinstance.py:2076} INFO - Dependencies all met for dep_context=non-requeueable deps ti=<TaskInstance: api_cuevana3_movie.execute_post_url_fastapi scheduled__2024-07-01T00:01:15+00:00 [queued]>
[2024-07-02T10:20:24.117-0400] {taskinstance.py:2076} INFO - Dependencies all met for dep_context=requeueable deps ti=<TaskInstance: api_cuevana3_movie.execute_post_url_fastapi scheduled__2024-07-01T00:01:15+00:00 [queued]>
[2024-07-02T10:20:24.117-0400] {taskinstance.py:2306} INFO - Starting attempt 1 of 1
[2024-07-02T10:20:24.147-0400] {taskinstance.py:2330} INFO - Executing <Task(PythonOperator): execute_post_url_fastapi> on 2024-07-01 00:01:15+00:00
[2024-07-02T10:20:24.155-0400] {standard_task_runner.py:63} INFO - Started process 495078 to run task
[2024-07-02T10:20:24.158-0400] {standard_task_runner.py:90} INFO - Running: ['airflow', 'tasks', 'run', 'api_cuevana3_movie', 'execute_post_url_fastapi', 'scheduled__2024-07-01T00:01:15+00:00', '--job-id', '1143', '--raw', '--subdir', 'DAGS_FOLDER/movie_recommend.py', '--cfg-path', '/tmp/tmpfb_ad19k']
[2024-07-02T10:20:24.159-0400] {standard_task_runner.py:91} INFO - Job 1143: Subtask execute_post_url_fastapi
[2024-07-02T10:20:24.196-0400] {task_command.py:426} INFO - Running <TaskInstance: api_cuevana3_movie.execute_post_url_fastapi scheduled__2024-07-01T00:01:15+00:00 [running]> on host walter-VirtualBox
[2024-07-02T10:20:24.284-0400] {taskinstance.py:2648} INFO - Exporting env vars: AIRFLOW_CTX_DAG_OWNER='airflow' AIRFLOW_CTX_DAG_ID='api_cuevana3_movie' AIRFLOW_CTX_TASK_ID='execute_post_url_fastapi' AIRFLOW_CTX_EXECUTION_DATE='2024-07-01T00:01:15+00:00' AIRFLOW_CTX_TRY_NUMBER='1' AIRFLOW_CTX_DAG_RUN_ID='scheduled__2024-07-01T00:01:15+00:00'
[2024-07-02T10:20:24.285-0400] {taskinstance.py:430} INFO - ::endgroup::
[2024-07-02T10:20:24.302-0400] {taskinstance.py:441} INFO - ::group::Post task execution logs
[2024-07-02T10:20:24.303-0400] {taskinstance.py:2905} ERROR - Task failed with exception
Traceback (most recent call last):
  File "/home/walter/Documentos/rakuntentv/venv/lib/python3.12/site-packages/urllib3/connection.py", line 196, in _new_conn
    sock = connection.create_connection(
           ^^^^^^^^^^^^^^^^^^^^^^^^^^^^^
  File "/home/walter/Documentos/rakuntentv/venv/lib/python3.12/site-packages/urllib3/util/connection.py", line 85, in create_connection
    raise err
  File "/home/walter/Documentos/rakuntentv/venv/lib/python3.12/site-packages/urllib3/util/connection.py", line 73, in create_connection
    sock.connect(sa)
ConnectionRefusedError: [Errno 111] Connection refused

The above exception was the direct cause of the following exception:

Traceback (most recent call last):
  File "/home/walter/Documentos/rakuntentv/venv/lib/python3.12/site-packages/urllib3/connectionpool.py", line 789, in urlopen
    response = self._make_request(
               ^^^^^^^^^^^^^^^^^^^
  File "/home/walter/Documentos/rakuntentv/venv/lib/python3.12/site-packages/urllib3/connectionpool.py", line 495, in _make_request
    conn.request(
  File "/home/walter/Documentos/rakuntentv/venv/lib/python3.12/site-packages/urllib3/connection.py", line 398, in request
    self.endheaders()
  File "/usr/lib/python3.12/http/client.py", line 1331, in endheaders
    self._send_output(message_body, encode_chunked=encode_chunked)
  File "/usr/lib/python3.12/http/client.py", line 1091, in _send_output
    self.send(msg)
  File "/usr/lib/python3.12/http/client.py", line 1035, in send
    self.connect()
  File "/home/walter/Documentos/rakuntentv/venv/lib/python3.12/site-packages/urllib3/connection.py", line 236, in connect
    self.sock = self._new_conn()
                ^^^^^^^^^^^^^^^^
  File "/home/walter/Documentos/rakuntentv/venv/lib/python3.12/site-packages/urllib3/connection.py", line 211, in _new_conn
    raise NewConnectionError(
urllib3.exceptions.NewConnectionError: <urllib3.connection.HTTPConnection object at 0x735862d6d670>: Failed to establish a new connection: [Errno 111] Connection refused

The above exception was the direct cause of the following exception:

Traceback (most recent call last):
  File "/home/walter/Documentos/rakuntentv/venv/lib/python3.12/site-packages/requests/adapters.py", line 667, in send
    resp = conn.urlopen(
           ^^^^^^^^^^^^^
  File "/home/walter/Documentos/rakuntentv/venv/lib/python3.12/site-packages/urllib3/connectionpool.py", line 843, in urlopen
    retries = retries.increment(
              ^^^^^^^^^^^^^^^^^^
  File "/home/walter/Documentos/rakuntentv/venv/lib/python3.12/site-packages/urllib3/util/retry.py", line 519, in increment
    raise MaxRetryError(_pool, url, reason) from reason  # type: ignore[arg-type]
    ^^^^^^^^^^^^^^^^^^^^^^^^^^^^^^^^^^^^^^^^^^^^^^^^^^^
urllib3.exceptions.MaxRetryError: HTTPConnectionPool(host='localhost', port=8000): Max retries exceeded with url: /scraper-url (Caused by NewConnectionError('<urllib3.connection.HTTPConnection object at 0x735862d6d670>: Failed to establish a new connection: [Errno 111] Connection refused'))

During handling of the above exception, another exception occurred:

Traceback (most recent call last):
  File "/home/walter/Documentos/rakuntentv/venv/lib/python3.12/site-packages/airflow/models/taskinstance.py", line 465, in _execute_task
    result = _execute_callable(context=context, **execute_callable_kwargs)
             ^^^^^^^^^^^^^^^^^^^^^^^^^^^^^^^^^^^^^^^^^^^^^^^^^^^^^^^^^^^^^
  File "/home/walter/Documentos/rakuntentv/venv/lib/python3.12/site-packages/airflow/models/taskinstance.py", line 432, in _execute_callable
    return execute_callable(context=context, **execute_callable_kwargs)
           ^^^^^^^^^^^^^^^^^^^^^^^^^^^^^^^^^^^^^^^^^^^^^^^^^^^^^^^^^^^^
  File "/home/walter/Documentos/rakuntentv/venv/lib/python3.12/site-packages/airflow/models/baseoperator.py", line 401, in wrapper
    return func(self, *args, **kwargs)
           ^^^^^^^^^^^^^^^^^^^^^^^^^^^
  File "/home/walter/Documentos/rakuntentv/venv/lib/python3.12/site-packages/airflow/operators/python.py", line 235, in execute
    return_value = self.execute_callable()
                   ^^^^^^^^^^^^^^^^^^^^^^^
  File "/home/walter/Documentos/rakuntentv/venv/lib/python3.12/site-packages/airflow/operators/python.py", line 252, in execute_callable
    return self.python_callable(*self.op_args, **self.op_kwargs)
           ^^^^^^^^^^^^^^^^^^^^^^^^^^^^^^^^^^^^^^^^^^^^^^^^^^^^^
  File "/home/walter/Documentos/rakuntentv/airflow/dags/movie_recommend.py", line 19, in execute_post_url_fastapi
    response = requests.post(api_url)
               ^^^^^^^^^^^^^^^^^^^^^^
  File "/home/walter/Documentos/rakuntentv/venv/lib/python3.12/site-packages/requests/api.py", line 115, in post
    return request("post", url, data=data, json=json, **kwargs)
           ^^^^^^^^^^^^^^^^^^^^^^^^^^^^^^^^^^^^^^^^^^^^^^^^^^^^
  File "/home/walter/Documentos/rakuntentv/venv/lib/python3.12/site-packages/requests/api.py", line 59, in request
    return session.request(method=method, url=url, **kwargs)
           ^^^^^^^^^^^^^^^^^^^^^^^^^^^^^^^^^^^^^^^^^^^^^^^^^
  File "/home/walter/Documentos/rakuntentv/venv/lib/python3.12/site-packages/requests/sessions.py", line 589, in request
    resp = self.send(prep, **send_kwargs)
           ^^^^^^^^^^^^^^^^^^^^^^^^^^^^^^
  File "/home/walter/Documentos/rakuntentv/venv/lib/python3.12/site-packages/requests/sessions.py", line 703, in send
    r = adapter.send(request, **kwargs)
        ^^^^^^^^^^^^^^^^^^^^^^^^^^^^^^^
  File "/home/walter/Documentos/rakuntentv/venv/lib/python3.12/site-packages/requests/adapters.py", line 700, in send
    raise ConnectionError(e, request=request)
requests.exceptions.ConnectionError: HTTPConnectionPool(host='localhost', port=8000): Max retries exceeded with url: /scraper-url (Caused by NewConnectionError('<urllib3.connection.HTTPConnection object at 0x735862d6d670>: Failed to establish a new connection: [Errno 111] Connection refused'))
[2024-07-02T10:20:24.308-0400] {taskinstance.py:1206} INFO - Marking task as FAILED. dag_id=api_cuevana3_movie, task_id=execute_post_url_fastapi, run_id=scheduled__2024-07-01T00:01:15+00:00, execution_date=20240701T000115, start_date=20240702T142024, end_date=20240702T142024
[2024-07-02T10:20:24.320-0400] {standard_task_runner.py:110} ERROR - Failed to execute job 1143 for task execute_post_url_fastapi (HTTPConnectionPool(host='localhost', port=8000): Max retries exceeded with url: /scraper-url (Caused by NewConnectionError('<urllib3.connection.HTTPConnection object at 0x735862d6d670>: Failed to establish a new connection: [Errno 111] Connection refused')); 495078)
[2024-07-02T10:20:24.342-0400] {local_task_job_runner.py:240} INFO - Task exited with return code 1
[2024-07-02T10:20:24.356-0400] {taskinstance.py:3503} INFO - 0 downstream tasks scheduled from follow-on schedule check
[2024-07-02T10:20:24.363-0400] {local_task_job_runner.py:222} INFO - ::endgroup::
[2024-07-02T10:39:29.689-0400] {local_task_job_runner.py:120} INFO - ::group::Pre task execution logs
[2024-07-02T10:39:29.711-0400] {taskinstance.py:2076} INFO - Dependencies all met for dep_context=non-requeueable deps ti=<TaskInstance: api_cuevana3_movie.execute_post_url_fastapi scheduled__2024-07-01T00:01:15+00:00 [queued]>
[2024-07-02T10:39:29.715-0400] {taskinstance.py:2076} INFO - Dependencies all met for dep_context=requeueable deps ti=<TaskInstance: api_cuevana3_movie.execute_post_url_fastapi scheduled__2024-07-01T00:01:15+00:00 [queued]>
[2024-07-02T10:39:29.716-0400] {taskinstance.py:2306} INFO - Starting attempt 1 of 1
[2024-07-02T10:39:29.738-0400] {taskinstance.py:2330} INFO - Executing <Task(PythonOperator): execute_post_url_fastapi> on 2024-07-01 00:01:15+00:00
[2024-07-02T10:39:29.745-0400] {standard_task_runner.py:63} INFO - Started process 497351 to run task
[2024-07-02T10:39:29.748-0400] {standard_task_runner.py:90} INFO - Running: ['airflow', 'tasks', 'run', 'api_cuevana3_movie', 'execute_post_url_fastapi', 'scheduled__2024-07-01T00:01:15+00:00', '--job-id', '1169', '--raw', '--subdir', 'DAGS_FOLDER/movie_recommend.py', '--cfg-path', '/tmp/tmpbr7l4gmy']
[2024-07-02T10:39:29.750-0400] {standard_task_runner.py:91} INFO - Job 1169: Subtask execute_post_url_fastapi
[2024-07-02T10:39:29.876-0400] {task_command.py:426} INFO - Running <TaskInstance: api_cuevana3_movie.execute_post_url_fastapi scheduled__2024-07-01T00:01:15+00:00 [running]> on host walter-VirtualBox
[2024-07-02T10:39:29.991-0400] {taskinstance.py:2648} INFO - Exporting env vars: AIRFLOW_CTX_DAG_OWNER='airflow' AIRFLOW_CTX_DAG_ID='api_cuevana3_movie' AIRFLOW_CTX_TASK_ID='execute_post_url_fastapi' AIRFLOW_CTX_EXECUTION_DATE='2024-07-01T00:01:15+00:00' AIRFLOW_CTX_TRY_NUMBER='1' AIRFLOW_CTX_DAG_RUN_ID='scheduled__2024-07-01T00:01:15+00:00'
[2024-07-02T10:39:29.993-0400] {taskinstance.py:430} INFO - ::endgroup::
[2024-07-02T10:39:31.910-0400] {logging_mixin.py:188} INFO - Scraping URL did not find any new URLs
[2024-07-02T10:39:31.912-0400] {python.py:237} INFO - Done. Returned value was: None
[2024-07-02T10:39:31.913-0400] {taskinstance.py:441} INFO - ::group::Post task execution logs
[2024-07-02T10:39:31.921-0400] {taskinstance.py:1206} INFO - Marking task as SUCCESS. dag_id=api_cuevana3_movie, task_id=execute_post_url_fastapi, run_id=scheduled__2024-07-01T00:01:15+00:00, execution_date=20240701T000115, start_date=20240702T143929, end_date=20240702T143931
[2024-07-02T10:39:31.957-0400] {local_task_job_runner.py:240} INFO - Task exited with return code 0
[2024-07-02T10:39:31.992-0400] {taskinstance.py:3503} INFO - 1 downstream tasks scheduled from follow-on schedule check
[2024-07-02T10:39:32.022-0400] {local_task_job_runner.py:222} INFO - ::endgroup::
[2024-07-02T10:56:18.937-0400] {local_task_job_runner.py:120} INFO - ::group::Pre task execution logs
[2024-07-02T10:56:18.954-0400] {taskinstance.py:2076} INFO - Dependencies all met for dep_context=non-requeueable deps ti=<TaskInstance: api_cuevana3_movie.execute_post_url_fastapi scheduled__2024-07-01T00:01:15+00:00 [queued]>
[2024-07-02T10:56:18.958-0400] {taskinstance.py:2076} INFO - Dependencies all met for dep_context=requeueable deps ti=<TaskInstance: api_cuevana3_movie.execute_post_url_fastapi scheduled__2024-07-01T00:01:15+00:00 [queued]>
[2024-07-02T10:56:18.958-0400] {taskinstance.py:2306} INFO - Starting attempt 1 of 1
[2024-07-02T10:56:18.972-0400] {taskinstance.py:2330} INFO - Executing <Task(PythonOperator): execute_post_url_fastapi> on 2024-07-01 00:01:15+00:00
[2024-07-02T10:56:18.977-0400] {standard_task_runner.py:63} INFO - Started process 500532 to run task
[2024-07-02T10:56:18.979-0400] {standard_task_runner.py:90} INFO - Running: ['airflow', 'tasks', 'run', 'api_cuevana3_movie', 'execute_post_url_fastapi', 'scheduled__2024-07-01T00:01:15+00:00', '--job-id', '1329', '--raw', '--subdir', 'DAGS_FOLDER/movie_recommend.py', '--cfg-path', '/tmp/tmp48gyj0vx']
[2024-07-02T10:56:18.981-0400] {standard_task_runner.py:91} INFO - Job 1329: Subtask execute_post_url_fastapi
[2024-07-02T10:56:19.014-0400] {task_command.py:426} INFO - Running <TaskInstance: api_cuevana3_movie.execute_post_url_fastapi scheduled__2024-07-01T00:01:15+00:00 [running]> on host walter-VirtualBox
[2024-07-02T10:56:19.111-0400] {taskinstance.py:2648} INFO - Exporting env vars: AIRFLOW_CTX_DAG_OWNER='airflow' AIRFLOW_CTX_DAG_ID='api_cuevana3_movie' AIRFLOW_CTX_TASK_ID='execute_post_url_fastapi' AIRFLOW_CTX_EXECUTION_DATE='2024-07-01T00:01:15+00:00' AIRFLOW_CTX_TRY_NUMBER='1' AIRFLOW_CTX_DAG_RUN_ID='scheduled__2024-07-01T00:01:15+00:00'
[2024-07-02T10:56:19.112-0400] {taskinstance.py:430} INFO - ::endgroup::
[2024-07-02T10:56:21.182-0400] {logging_mixin.py:188} INFO - Scraping URL did not find any new URLs
[2024-07-02T10:56:21.182-0400] {python.py:237} INFO - Done. Returned value was: None
[2024-07-02T10:56:21.183-0400] {taskinstance.py:441} INFO - ::group::Post task execution logs
[2024-07-02T10:56:21.207-0400] {taskinstance.py:1206} INFO - Marking task as SUCCESS. dag_id=api_cuevana3_movie, task_id=execute_post_url_fastapi, run_id=scheduled__2024-07-01T00:01:15+00:00, execution_date=20240701T000115, start_date=20240702T145618, end_date=20240702T145621
[2024-07-02T10:56:21.288-0400] {local_task_job_runner.py:240} INFO - Task exited with return code 0
[2024-07-02T10:56:21.363-0400] {taskinstance.py:3503} INFO - 1 downstream tasks scheduled from follow-on schedule check
[2024-07-02T10:56:21.405-0400] {local_task_job_runner.py:222} INFO - ::endgroup::
[2024-07-02T11:26:44.887-0400] {local_task_job_runner.py:120} INFO - ::group::Pre task execution logs
[2024-07-02T11:26:44.912-0400] {taskinstance.py:2076} INFO - Dependencies all met for dep_context=non-requeueable deps ti=<TaskInstance: api_cuevana3_movie.execute_post_url_fastapi scheduled__2024-07-01T00:01:15+00:00 [queued]>
[2024-07-02T11:26:44.917-0400] {taskinstance.py:2076} INFO - Dependencies all met for dep_context=requeueable deps ti=<TaskInstance: api_cuevana3_movie.execute_post_url_fastapi scheduled__2024-07-01T00:01:15+00:00 [queued]>
[2024-07-02T11:26:44.917-0400] {taskinstance.py:2306} INFO - Starting attempt 1 of 1
[2024-07-02T11:26:44.934-0400] {taskinstance.py:2330} INFO - Executing <Task(PythonOperator): execute_post_url_fastapi> on 2024-07-01 00:01:15+00:00
[2024-07-02T11:26:44.940-0400] {standard_task_runner.py:63} INFO - Started process 503436 to run task
[2024-07-02T11:26:44.946-0400] {standard_task_runner.py:90} INFO - Running: ['airflow', 'tasks', 'run', 'api_cuevana3_movie', 'execute_post_url_fastapi', 'scheduled__2024-07-01T00:01:15+00:00', '--job-id', '1357', '--raw', '--subdir', 'DAGS_FOLDER/movie_recommend.py', '--cfg-path', '/tmp/tmplj1qmtov']
[2024-07-02T11:26:44.948-0400] {standard_task_runner.py:91} INFO - Job 1357: Subtask execute_post_url_fastapi
[2024-07-02T11:26:45.048-0400] {task_command.py:426} INFO - Running <TaskInstance: api_cuevana3_movie.execute_post_url_fastapi scheduled__2024-07-01T00:01:15+00:00 [running]> on host walter-VirtualBox
[2024-07-02T11:26:45.199-0400] {taskinstance.py:2648} INFO - Exporting env vars: AIRFLOW_CTX_DAG_OWNER='airflow' AIRFLOW_CTX_DAG_ID='api_cuevana3_movie' AIRFLOW_CTX_TASK_ID='execute_post_url_fastapi' AIRFLOW_CTX_EXECUTION_DATE='2024-07-01T00:01:15+00:00' AIRFLOW_CTX_TRY_NUMBER='1' AIRFLOW_CTX_DAG_RUN_ID='scheduled__2024-07-01T00:01:15+00:00'
[2024-07-02T11:26:45.199-0400] {taskinstance.py:430} INFO - ::endgroup::
[2024-07-02T11:26:45.231-0400] {taskinstance.py:441} INFO - ::group::Post task execution logs
[2024-07-02T11:26:45.234-0400] {taskinstance.py:2905} ERROR - Task failed with exception
Traceback (most recent call last):
  File "/home/walter/Documentos/rakuntentv/venv/lib/python3.12/site-packages/urllib3/connection.py", line 196, in _new_conn
    sock = connection.create_connection(
           ^^^^^^^^^^^^^^^^^^^^^^^^^^^^^
  File "/home/walter/Documentos/rakuntentv/venv/lib/python3.12/site-packages/urllib3/util/connection.py", line 85, in create_connection
    raise err
  File "/home/walter/Documentos/rakuntentv/venv/lib/python3.12/site-packages/urllib3/util/connection.py", line 73, in create_connection
    sock.connect(sa)
ConnectionRefusedError: [Errno 111] Connection refused

The above exception was the direct cause of the following exception:

Traceback (most recent call last):
  File "/home/walter/Documentos/rakuntentv/venv/lib/python3.12/site-packages/urllib3/connectionpool.py", line 789, in urlopen
    response = self._make_request(
               ^^^^^^^^^^^^^^^^^^^
  File "/home/walter/Documentos/rakuntentv/venv/lib/python3.12/site-packages/urllib3/connectionpool.py", line 495, in _make_request
    conn.request(
  File "/home/walter/Documentos/rakuntentv/venv/lib/python3.12/site-packages/urllib3/connection.py", line 398, in request
    self.endheaders()
  File "/usr/lib/python3.12/http/client.py", line 1331, in endheaders
    self._send_output(message_body, encode_chunked=encode_chunked)
  File "/usr/lib/python3.12/http/client.py", line 1091, in _send_output
    self.send(msg)
  File "/usr/lib/python3.12/http/client.py", line 1035, in send
    self.connect()
  File "/home/walter/Documentos/rakuntentv/venv/lib/python3.12/site-packages/urllib3/connection.py", line 236, in connect
    self.sock = self._new_conn()
                ^^^^^^^^^^^^^^^^
  File "/home/walter/Documentos/rakuntentv/venv/lib/python3.12/site-packages/urllib3/connection.py", line 211, in _new_conn
    raise NewConnectionError(
urllib3.exceptions.NewConnectionError: <urllib3.connection.HTTPConnection object at 0x728747b5e420>: Failed to establish a new connection: [Errno 111] Connection refused

The above exception was the direct cause of the following exception:

Traceback (most recent call last):
  File "/home/walter/Documentos/rakuntentv/venv/lib/python3.12/site-packages/requests/adapters.py", line 667, in send
    resp = conn.urlopen(
           ^^^^^^^^^^^^^
  File "/home/walter/Documentos/rakuntentv/venv/lib/python3.12/site-packages/urllib3/connectionpool.py", line 843, in urlopen
    retries = retries.increment(
              ^^^^^^^^^^^^^^^^^^
  File "/home/walter/Documentos/rakuntentv/venv/lib/python3.12/site-packages/urllib3/util/retry.py", line 519, in increment
    raise MaxRetryError(_pool, url, reason) from reason  # type: ignore[arg-type]
    ^^^^^^^^^^^^^^^^^^^^^^^^^^^^^^^^^^^^^^^^^^^^^^^^^^^
urllib3.exceptions.MaxRetryError: HTTPConnectionPool(host='localhost', port=8000): Max retries exceeded with url: /scraper-url (Caused by NewConnectionError('<urllib3.connection.HTTPConnection object at 0x728747b5e420>: Failed to establish a new connection: [Errno 111] Connection refused'))

During handling of the above exception, another exception occurred:

Traceback (most recent call last):
  File "/home/walter/Documentos/rakuntentv/venv/lib/python3.12/site-packages/airflow/models/taskinstance.py", line 465, in _execute_task
    result = _execute_callable(context=context, **execute_callable_kwargs)
             ^^^^^^^^^^^^^^^^^^^^^^^^^^^^^^^^^^^^^^^^^^^^^^^^^^^^^^^^^^^^^
  File "/home/walter/Documentos/rakuntentv/venv/lib/python3.12/site-packages/airflow/models/taskinstance.py", line 432, in _execute_callable
    return execute_callable(context=context, **execute_callable_kwargs)
           ^^^^^^^^^^^^^^^^^^^^^^^^^^^^^^^^^^^^^^^^^^^^^^^^^^^^^^^^^^^^
  File "/home/walter/Documentos/rakuntentv/venv/lib/python3.12/site-packages/airflow/models/baseoperator.py", line 401, in wrapper
    return func(self, *args, **kwargs)
           ^^^^^^^^^^^^^^^^^^^^^^^^^^^
  File "/home/walter/Documentos/rakuntentv/venv/lib/python3.12/site-packages/airflow/operators/python.py", line 235, in execute
    return_value = self.execute_callable()
                   ^^^^^^^^^^^^^^^^^^^^^^^
  File "/home/walter/Documentos/rakuntentv/venv/lib/python3.12/site-packages/airflow/operators/python.py", line 252, in execute_callable
    return self.python_callable(*self.op_args, **self.op_kwargs)
           ^^^^^^^^^^^^^^^^^^^^^^^^^^^^^^^^^^^^^^^^^^^^^^^^^^^^^
  File "/home/walter/Documentos/rakuntentv/airflow/dags/movie_recommend.py", line 19, in execute_post_url_fastapi
    response = requests.post(api_url)
               ^^^^^^^^^^^^^^^^^^^^^^
  File "/home/walter/Documentos/rakuntentv/venv/lib/python3.12/site-packages/requests/api.py", line 115, in post
    return request("post", url, data=data, json=json, **kwargs)
           ^^^^^^^^^^^^^^^^^^^^^^^^^^^^^^^^^^^^^^^^^^^^^^^^^^^^
  File "/home/walter/Documentos/rakuntentv/venv/lib/python3.12/site-packages/requests/api.py", line 59, in request
    return session.request(method=method, url=url, **kwargs)
           ^^^^^^^^^^^^^^^^^^^^^^^^^^^^^^^^^^^^^^^^^^^^^^^^^
  File "/home/walter/Documentos/rakuntentv/venv/lib/python3.12/site-packages/requests/sessions.py", line 589, in request
    resp = self.send(prep, **send_kwargs)
           ^^^^^^^^^^^^^^^^^^^^^^^^^^^^^^
  File "/home/walter/Documentos/rakuntentv/venv/lib/python3.12/site-packages/requests/sessions.py", line 703, in send
    r = adapter.send(request, **kwargs)
        ^^^^^^^^^^^^^^^^^^^^^^^^^^^^^^^
  File "/home/walter/Documentos/rakuntentv/venv/lib/python3.12/site-packages/requests/adapters.py", line 700, in send
    raise ConnectionError(e, request=request)
requests.exceptions.ConnectionError: HTTPConnectionPool(host='localhost', port=8000): Max retries exceeded with url: /scraper-url (Caused by NewConnectionError('<urllib3.connection.HTTPConnection object at 0x728747b5e420>: Failed to establish a new connection: [Errno 111] Connection refused'))
[2024-07-02T11:26:45.274-0400] {taskinstance.py:1206} INFO - Marking task as FAILED. dag_id=api_cuevana3_movie, task_id=execute_post_url_fastapi, run_id=scheduled__2024-07-01T00:01:15+00:00, execution_date=20240701T000115, start_date=20240702T152644, end_date=20240702T152645
[2024-07-02T11:26:45.343-0400] {standard_task_runner.py:110} ERROR - Failed to execute job 1357 for task execute_post_url_fastapi (HTTPConnectionPool(host='localhost', port=8000): Max retries exceeded with url: /scraper-url (Caused by NewConnectionError('<urllib3.connection.HTTPConnection object at 0x728747b5e420>: Failed to establish a new connection: [Errno 111] Connection refused')); 503436)
[2024-07-02T11:26:45.390-0400] {local_task_job_runner.py:240} INFO - Task exited with return code 1
[2024-07-02T11:26:45.408-0400] {taskinstance.py:3503} INFO - 0 downstream tasks scheduled from follow-on schedule check
[2024-07-02T11:26:45.424-0400] {local_task_job_runner.py:222} INFO - ::endgroup::
