[2024-07-02T09:41:12.721-0400] {local_task_job_runner.py:120} INFO - ::group::Pre task execution logs
[2024-07-02T09:41:12.758-0400] {taskinstance.py:2076} INFO - Dependencies all met for dep_context=non-requeueable deps ti=<TaskInstance: api_cuevana3_movie.execute_post_url_fastapi scheduled__2024-07-01T00:01:45+00:00 [queued]>
[2024-07-02T09:41:12.764-0400] {taskinstance.py:2076} INFO - Dependencies all met for dep_context=requeueable deps ti=<TaskInstance: api_cuevana3_movie.execute_post_url_fastapi scheduled__2024-07-01T00:01:45+00:00 [queued]>
[2024-07-02T09:41:12.767-0400] {taskinstance.py:2306} INFO - Starting attempt 1 of 1
[2024-07-02T09:41:12.824-0400] {taskinstance.py:2330} INFO - Executing <Task(PythonOperator): execute_post_url_fastapi> on 2024-07-01 00:01:45+00:00
[2024-07-02T09:41:12.830-0400] {standard_task_runner.py:63} INFO - Started process 483102 to run task
[2024-07-02T09:41:12.837-0400] {standard_task_runner.py:90} INFO - Running: ['airflow', 'tasks', 'run', 'api_cuevana3_movie', 'execute_post_url_fastapi', 'scheduled__2024-07-01T00:01:45+00:00', '--job-id', '974', '--raw', '--subdir', 'DAGS_FOLDER/movie_recommend.py', '--cfg-path', '/tmp/tmpxtwkk272']
[2024-07-02T09:41:12.839-0400] {standard_task_runner.py:91} INFO - Job 974: Subtask execute_post_url_fastapi
[2024-07-02T09:41:12.900-0400] {task_command.py:426} INFO - Running <TaskInstance: api_cuevana3_movie.execute_post_url_fastapi scheduled__2024-07-01T00:01:45+00:00 [running]> on host walter-VirtualBox
[2024-07-02T09:41:13.034-0400] {taskinstance.py:2648} INFO - Exporting env vars: AIRFLOW_CTX_DAG_OWNER='airflow' AIRFLOW_CTX_DAG_ID='api_cuevana3_movie' AIRFLOW_CTX_TASK_ID='execute_post_url_fastapi' AIRFLOW_CTX_EXECUTION_DATE='2024-07-01T00:01:45+00:00' AIRFLOW_CTX_TRY_NUMBER='1' AIRFLOW_CTX_DAG_RUN_ID='scheduled__2024-07-01T00:01:45+00:00'
[2024-07-02T09:41:13.035-0400] {taskinstance.py:430} INFO - ::endgroup::
[2024-07-02T09:41:13.067-0400] {taskinstance.py:441} INFO - ::group::Post task execution logs
[2024-07-02T09:41:13.068-0400] {taskinstance.py:2905} ERROR - Task failed with exception
Traceback (most recent call last):
  File "/home/walter/Documentos/rakuntentv/venv/lib/python3.12/site-packages/urllib3/connection.py", line 196, in _new_conn
    sock = connection.create_connection(
           ^^^^^^^^^^^^^^^^^^^^^^^^^^^^^
  File "/home/walter/Documentos/rakuntentv/venv/lib/python3.12/site-packages/urllib3/util/connection.py", line 85, in create_connection
    raise err
  File "/home/walter/Documentos/rakuntentv/venv/lib/python3.12/site-packages/urllib3/util/connection.py", line 73, in create_connection
    sock.connect(sa)
ConnectionRefusedError: [Errno 111] Connection refused

The above exception was the direct cause of the following exception:

Traceback (most recent call last):
  File "/home/walter/Documentos/rakuntentv/venv/lib/python3.12/site-packages/urllib3/connectionpool.py", line 789, in urlopen
    response = self._make_request(
               ^^^^^^^^^^^^^^^^^^^
  File "/home/walter/Documentos/rakuntentv/venv/lib/python3.12/site-packages/urllib3/connectionpool.py", line 495, in _make_request
    conn.request(
  File "/home/walter/Documentos/rakuntentv/venv/lib/python3.12/site-packages/urllib3/connection.py", line 398, in request
    self.endheaders()
  File "/usr/lib/python3.12/http/client.py", line 1331, in endheaders
    self._send_output(message_body, encode_chunked=encode_chunked)
  File "/usr/lib/python3.12/http/client.py", line 1091, in _send_output
    self.send(msg)
  File "/usr/lib/python3.12/http/client.py", line 1035, in send
    self.connect()
  File "/home/walter/Documentos/rakuntentv/venv/lib/python3.12/site-packages/urllib3/connection.py", line 236, in connect
    self.sock = self._new_conn()
                ^^^^^^^^^^^^^^^^
  File "/home/walter/Documentos/rakuntentv/venv/lib/python3.12/site-packages/urllib3/connection.py", line 211, in _new_conn
    raise NewConnectionError(
urllib3.exceptions.NewConnectionError: <urllib3.connection.HTTPConnection object at 0x7004876ccc80>: Failed to establish a new connection: [Errno 111] Connection refused

The above exception was the direct cause of the following exception:

Traceback (most recent call last):
  File "/home/walter/Documentos/rakuntentv/venv/lib/python3.12/site-packages/requests/adapters.py", line 667, in send
    resp = conn.urlopen(
           ^^^^^^^^^^^^^
  File "/home/walter/Documentos/rakuntentv/venv/lib/python3.12/site-packages/urllib3/connectionpool.py", line 843, in urlopen
    retries = retries.increment(
              ^^^^^^^^^^^^^^^^^^
  File "/home/walter/Documentos/rakuntentv/venv/lib/python3.12/site-packages/urllib3/util/retry.py", line 519, in increment
    raise MaxRetryError(_pool, url, reason) from reason  # type: ignore[arg-type]
    ^^^^^^^^^^^^^^^^^^^^^^^^^^^^^^^^^^^^^^^^^^^^^^^^^^^
urllib3.exceptions.MaxRetryError: HTTPConnectionPool(host='localhost', port=8000): Max retries exceeded with url: /scraper-url (Caused by NewConnectionError('<urllib3.connection.HTTPConnection object at 0x7004876ccc80>: Failed to establish a new connection: [Errno 111] Connection refused'))

During handling of the above exception, another exception occurred:

Traceback (most recent call last):
  File "/home/walter/Documentos/rakuntentv/venv/lib/python3.12/site-packages/airflow/models/taskinstance.py", line 465, in _execute_task
    result = _execute_callable(context=context, **execute_callable_kwargs)
             ^^^^^^^^^^^^^^^^^^^^^^^^^^^^^^^^^^^^^^^^^^^^^^^^^^^^^^^^^^^^^
  File "/home/walter/Documentos/rakuntentv/venv/lib/python3.12/site-packages/airflow/models/taskinstance.py", line 432, in _execute_callable
    return execute_callable(context=context, **execute_callable_kwargs)
           ^^^^^^^^^^^^^^^^^^^^^^^^^^^^^^^^^^^^^^^^^^^^^^^^^^^^^^^^^^^^
  File "/home/walter/Documentos/rakuntentv/venv/lib/python3.12/site-packages/airflow/models/baseoperator.py", line 401, in wrapper
    return func(self, *args, **kwargs)
           ^^^^^^^^^^^^^^^^^^^^^^^^^^^
  File "/home/walter/Documentos/rakuntentv/venv/lib/python3.12/site-packages/airflow/operators/python.py", line 235, in execute
    return_value = self.execute_callable()
                   ^^^^^^^^^^^^^^^^^^^^^^^
  File "/home/walter/Documentos/rakuntentv/venv/lib/python3.12/site-packages/airflow/operators/python.py", line 252, in execute_callable
    return self.python_callable(*self.op_args, **self.op_kwargs)
           ^^^^^^^^^^^^^^^^^^^^^^^^^^^^^^^^^^^^^^^^^^^^^^^^^^^^^
  File "/home/walter/Documentos/rakuntentv/airflow/dags/movie_recommend.py", line 19, in execute_post_url_fastapi
    response = requests.post(api_url)
               ^^^^^^^^^^^^^^^^^^^^^^
  File "/home/walter/Documentos/rakuntentv/venv/lib/python3.12/site-packages/requests/api.py", line 115, in post
    return request("post", url, data=data, json=json, **kwargs)
           ^^^^^^^^^^^^^^^^^^^^^^^^^^^^^^^^^^^^^^^^^^^^^^^^^^^^
  File "/home/walter/Documentos/rakuntentv/venv/lib/python3.12/site-packages/requests/api.py", line 59, in request
    return session.request(method=method, url=url, **kwargs)
           ^^^^^^^^^^^^^^^^^^^^^^^^^^^^^^^^^^^^^^^^^^^^^^^^^
  File "/home/walter/Documentos/rakuntentv/venv/lib/python3.12/site-packages/requests/sessions.py", line 589, in request
    resp = self.send(prep, **send_kwargs)
           ^^^^^^^^^^^^^^^^^^^^^^^^^^^^^^
  File "/home/walter/Documentos/rakuntentv/venv/lib/python3.12/site-packages/requests/sessions.py", line 703, in send
    r = adapter.send(request, **kwargs)
        ^^^^^^^^^^^^^^^^^^^^^^^^^^^^^^^
  File "/home/walter/Documentos/rakuntentv/venv/lib/python3.12/site-packages/requests/adapters.py", line 700, in send
    raise ConnectionError(e, request=request)
requests.exceptions.ConnectionError: HTTPConnectionPool(host='localhost', port=8000): Max retries exceeded with url: /scraper-url (Caused by NewConnectionError('<urllib3.connection.HTTPConnection object at 0x7004876ccc80>: Failed to establish a new connection: [Errno 111] Connection refused'))
[2024-07-02T09:41:13.091-0400] {taskinstance.py:1206} INFO - Marking task as FAILED. dag_id=api_cuevana3_movie, task_id=execute_post_url_fastapi, run_id=scheduled__2024-07-01T00:01:45+00:00, execution_date=20240701T000145, start_date=20240702T134112, end_date=20240702T134113
[2024-07-02T09:41:13.111-0400] {standard_task_runner.py:110} ERROR - Failed to execute job 974 for task execute_post_url_fastapi (HTTPConnectionPool(host='localhost', port=8000): Max retries exceeded with url: /scraper-url (Caused by NewConnectionError('<urllib3.connection.HTTPConnection object at 0x7004876ccc80>: Failed to establish a new connection: [Errno 111] Connection refused')); 483102)
[2024-07-02T09:41:13.148-0400] {local_task_job_runner.py:240} INFO - Task exited with return code 1
[2024-07-02T09:41:13.168-0400] {taskinstance.py:3503} INFO - 0 downstream tasks scheduled from follow-on schedule check
[2024-07-02T09:41:13.199-0400] {local_task_job_runner.py:222} INFO - ::endgroup::
[2024-07-02T10:20:33.328-0400] {local_task_job_runner.py:120} INFO - ::group::Pre task execution logs
[2024-07-02T10:20:33.360-0400] {taskinstance.py:2076} INFO - Dependencies all met for dep_context=non-requeueable deps ti=<TaskInstance: api_cuevana3_movie.execute_post_url_fastapi scheduled__2024-07-01T00:01:45+00:00 [queued]>
[2024-07-02T10:20:33.366-0400] {taskinstance.py:2076} INFO - Dependencies all met for dep_context=requeueable deps ti=<TaskInstance: api_cuevana3_movie.execute_post_url_fastapi scheduled__2024-07-01T00:01:45+00:00 [queued]>
[2024-07-02T10:20:33.366-0400] {taskinstance.py:2306} INFO - Starting attempt 1 of 1
[2024-07-02T10:20:33.423-0400] {taskinstance.py:2330} INFO - Executing <Task(PythonOperator): execute_post_url_fastapi> on 2024-07-01 00:01:45+00:00
[2024-07-02T10:20:33.434-0400] {standard_task_runner.py:63} INFO - Started process 495159 to run task
[2024-07-02T10:20:33.441-0400] {standard_task_runner.py:90} INFO - Running: ['airflow', 'tasks', 'run', 'api_cuevana3_movie', 'execute_post_url_fastapi', 'scheduled__2024-07-01T00:01:45+00:00', '--job-id', '1145', '--raw', '--subdir', 'DAGS_FOLDER/movie_recommend.py', '--cfg-path', '/tmp/tmpkdtjflq0']
[2024-07-02T10:20:33.444-0400] {standard_task_runner.py:91} INFO - Job 1145: Subtask execute_post_url_fastapi
[2024-07-02T10:20:33.561-0400] {task_command.py:426} INFO - Running <TaskInstance: api_cuevana3_movie.execute_post_url_fastapi scheduled__2024-07-01T00:01:45+00:00 [running]> on host walter-VirtualBox
[2024-07-02T10:20:33.687-0400] {taskinstance.py:2648} INFO - Exporting env vars: AIRFLOW_CTX_DAG_OWNER='airflow' AIRFLOW_CTX_DAG_ID='api_cuevana3_movie' AIRFLOW_CTX_TASK_ID='execute_post_url_fastapi' AIRFLOW_CTX_EXECUTION_DATE='2024-07-01T00:01:45+00:00' AIRFLOW_CTX_TRY_NUMBER='1' AIRFLOW_CTX_DAG_RUN_ID='scheduled__2024-07-01T00:01:45+00:00'
[2024-07-02T10:20:33.689-0400] {taskinstance.py:430} INFO - ::endgroup::
[2024-07-02T10:20:35.704-0400] {logging_mixin.py:188} INFO - Scraping URL did not find any new URLs
[2024-07-02T10:20:35.704-0400] {python.py:237} INFO - Done. Returned value was: None
[2024-07-02T10:20:35.705-0400] {taskinstance.py:441} INFO - ::group::Post task execution logs
[2024-07-02T10:20:35.714-0400] {taskinstance.py:1206} INFO - Marking task as SUCCESS. dag_id=api_cuevana3_movie, task_id=execute_post_url_fastapi, run_id=scheduled__2024-07-01T00:01:45+00:00, execution_date=20240701T000145, start_date=20240702T142033, end_date=20240702T142035
[2024-07-02T10:20:35.813-0400] {local_task_job_runner.py:240} INFO - Task exited with return code 0
[2024-07-02T10:20:35.853-0400] {taskinstance.py:3503} INFO - 1 downstream tasks scheduled from follow-on schedule check
[2024-07-02T10:20:35.876-0400] {local_task_job_runner.py:222} INFO - ::endgroup::
[2024-07-02T10:41:49.274-0400] {local_task_job_runner.py:120} INFO - ::group::Pre task execution logs
[2024-07-02T10:41:49.297-0400] {taskinstance.py:2076} INFO - Dependencies all met for dep_context=non-requeueable deps ti=<TaskInstance: api_cuevana3_movie.execute_post_url_fastapi scheduled__2024-07-01T00:01:45+00:00 [queued]>
[2024-07-02T10:41:49.308-0400] {taskinstance.py:2076} INFO - Dependencies all met for dep_context=requeueable deps ti=<TaskInstance: api_cuevana3_movie.execute_post_url_fastapi scheduled__2024-07-01T00:01:45+00:00 [queued]>
[2024-07-02T10:41:49.308-0400] {taskinstance.py:2306} INFO - Starting attempt 1 of 1
[2024-07-02T10:41:49.343-0400] {taskinstance.py:2330} INFO - Executing <Task(PythonOperator): execute_post_url_fastapi> on 2024-07-01 00:01:45+00:00
[2024-07-02T10:41:49.355-0400] {standard_task_runner.py:63} INFO - Started process 498075 to run task
[2024-07-02T10:41:49.364-0400] {standard_task_runner.py:90} INFO - Running: ['airflow', 'tasks', 'run', 'api_cuevana3_movie', 'execute_post_url_fastapi', 'scheduled__2024-07-01T00:01:45+00:00', '--job-id', '1182', '--raw', '--subdir', 'DAGS_FOLDER/movie_recommend.py', '--cfg-path', '/tmp/tmp4kkj1v5w']
[2024-07-02T10:41:49.366-0400] {standard_task_runner.py:91} INFO - Job 1182: Subtask execute_post_url_fastapi
[2024-07-02T10:41:49.466-0400] {task_command.py:426} INFO - Running <TaskInstance: api_cuevana3_movie.execute_post_url_fastapi scheduled__2024-07-01T00:01:45+00:00 [running]> on host walter-VirtualBox
[2024-07-02T10:41:49.574-0400] {taskinstance.py:2648} INFO - Exporting env vars: AIRFLOW_CTX_DAG_OWNER='airflow' AIRFLOW_CTX_DAG_ID='api_cuevana3_movie' AIRFLOW_CTX_TASK_ID='execute_post_url_fastapi' AIRFLOW_CTX_EXECUTION_DATE='2024-07-01T00:01:45+00:00' AIRFLOW_CTX_TRY_NUMBER='1' AIRFLOW_CTX_DAG_RUN_ID='scheduled__2024-07-01T00:01:45+00:00'
[2024-07-02T10:41:49.575-0400] {taskinstance.py:430} INFO - ::endgroup::
[2024-07-02T10:41:49.604-0400] {taskinstance.py:441} INFO - ::group::Post task execution logs
[2024-07-02T10:41:49.608-0400] {taskinstance.py:2905} ERROR - Task failed with exception
Traceback (most recent call last):
  File "/home/walter/Documentos/rakuntentv/venv/lib/python3.12/site-packages/urllib3/connection.py", line 196, in _new_conn
    sock = connection.create_connection(
           ^^^^^^^^^^^^^^^^^^^^^^^^^^^^^
  File "/home/walter/Documentos/rakuntentv/venv/lib/python3.12/site-packages/urllib3/util/connection.py", line 85, in create_connection
    raise err
  File "/home/walter/Documentos/rakuntentv/venv/lib/python3.12/site-packages/urllib3/util/connection.py", line 73, in create_connection
    sock.connect(sa)
ConnectionRefusedError: [Errno 111] Connection refused

The above exception was the direct cause of the following exception:

Traceback (most recent call last):
  File "/home/walter/Documentos/rakuntentv/venv/lib/python3.12/site-packages/urllib3/connectionpool.py", line 789, in urlopen
    response = self._make_request(
               ^^^^^^^^^^^^^^^^^^^
  File "/home/walter/Documentos/rakuntentv/venv/lib/python3.12/site-packages/urllib3/connectionpool.py", line 495, in _make_request
    conn.request(
  File "/home/walter/Documentos/rakuntentv/venv/lib/python3.12/site-packages/urllib3/connection.py", line 398, in request
    self.endheaders()
  File "/usr/lib/python3.12/http/client.py", line 1331, in endheaders
    self._send_output(message_body, encode_chunked=encode_chunked)
  File "/usr/lib/python3.12/http/client.py", line 1091, in _send_output
    self.send(msg)
  File "/usr/lib/python3.12/http/client.py", line 1035, in send
    self.connect()
  File "/home/walter/Documentos/rakuntentv/venv/lib/python3.12/site-packages/urllib3/connection.py", line 236, in connect
    self.sock = self._new_conn()
                ^^^^^^^^^^^^^^^^
  File "/home/walter/Documentos/rakuntentv/venv/lib/python3.12/site-packages/urllib3/connection.py", line 211, in _new_conn
    raise NewConnectionError(
urllib3.exceptions.NewConnectionError: <urllib3.connection.HTTPConnection object at 0x7580b27574d0>: Failed to establish a new connection: [Errno 111] Connection refused

The above exception was the direct cause of the following exception:

Traceback (most recent call last):
  File "/home/walter/Documentos/rakuntentv/venv/lib/python3.12/site-packages/requests/adapters.py", line 667, in send
    resp = conn.urlopen(
           ^^^^^^^^^^^^^
  File "/home/walter/Documentos/rakuntentv/venv/lib/python3.12/site-packages/urllib3/connectionpool.py", line 843, in urlopen
    retries = retries.increment(
              ^^^^^^^^^^^^^^^^^^
  File "/home/walter/Documentos/rakuntentv/venv/lib/python3.12/site-packages/urllib3/util/retry.py", line 519, in increment
    raise MaxRetryError(_pool, url, reason) from reason  # type: ignore[arg-type]
    ^^^^^^^^^^^^^^^^^^^^^^^^^^^^^^^^^^^^^^^^^^^^^^^^^^^
urllib3.exceptions.MaxRetryError: HTTPConnectionPool(host='localhost', port=8000): Max retries exceeded with url: /scraper-url (Caused by NewConnectionError('<urllib3.connection.HTTPConnection object at 0x7580b27574d0>: Failed to establish a new connection: [Errno 111] Connection refused'))

During handling of the above exception, another exception occurred:

Traceback (most recent call last):
  File "/home/walter/Documentos/rakuntentv/venv/lib/python3.12/site-packages/airflow/models/taskinstance.py", line 465, in _execute_task
    result = _execute_callable(context=context, **execute_callable_kwargs)
             ^^^^^^^^^^^^^^^^^^^^^^^^^^^^^^^^^^^^^^^^^^^^^^^^^^^^^^^^^^^^^
  File "/home/walter/Documentos/rakuntentv/venv/lib/python3.12/site-packages/airflow/models/taskinstance.py", line 432, in _execute_callable
    return execute_callable(context=context, **execute_callable_kwargs)
           ^^^^^^^^^^^^^^^^^^^^^^^^^^^^^^^^^^^^^^^^^^^^^^^^^^^^^^^^^^^^
  File "/home/walter/Documentos/rakuntentv/venv/lib/python3.12/site-packages/airflow/models/baseoperator.py", line 401, in wrapper
    return func(self, *args, **kwargs)
           ^^^^^^^^^^^^^^^^^^^^^^^^^^^
  File "/home/walter/Documentos/rakuntentv/venv/lib/python3.12/site-packages/airflow/operators/python.py", line 235, in execute
    return_value = self.execute_callable()
                   ^^^^^^^^^^^^^^^^^^^^^^^
  File "/home/walter/Documentos/rakuntentv/venv/lib/python3.12/site-packages/airflow/operators/python.py", line 252, in execute_callable
    return self.python_callable(*self.op_args, **self.op_kwargs)
           ^^^^^^^^^^^^^^^^^^^^^^^^^^^^^^^^^^^^^^^^^^^^^^^^^^^^^
  File "/home/walter/Documentos/rakuntentv/airflow/dags/movie_recommend.py", line 19, in execute_post_url_fastapi
    response = requests.post(api_url)
               ^^^^^^^^^^^^^^^^^^^^^^
  File "/home/walter/Documentos/rakuntentv/venv/lib/python3.12/site-packages/requests/api.py", line 115, in post
    return request("post", url, data=data, json=json, **kwargs)
           ^^^^^^^^^^^^^^^^^^^^^^^^^^^^^^^^^^^^^^^^^^^^^^^^^^^^
  File "/home/walter/Documentos/rakuntentv/venv/lib/python3.12/site-packages/requests/api.py", line 59, in request
    return session.request(method=method, url=url, **kwargs)
           ^^^^^^^^^^^^^^^^^^^^^^^^^^^^^^^^^^^^^^^^^^^^^^^^^
  File "/home/walter/Documentos/rakuntentv/venv/lib/python3.12/site-packages/requests/sessions.py", line 589, in request
    resp = self.send(prep, **send_kwargs)
           ^^^^^^^^^^^^^^^^^^^^^^^^^^^^^^
  File "/home/walter/Documentos/rakuntentv/venv/lib/python3.12/site-packages/requests/sessions.py", line 703, in send
    r = adapter.send(request, **kwargs)
        ^^^^^^^^^^^^^^^^^^^^^^^^^^^^^^^
  File "/home/walter/Documentos/rakuntentv/venv/lib/python3.12/site-packages/requests/adapters.py", line 700, in send
    raise ConnectionError(e, request=request)
requests.exceptions.ConnectionError: HTTPConnectionPool(host='localhost', port=8000): Max retries exceeded with url: /scraper-url (Caused by NewConnectionError('<urllib3.connection.HTTPConnection object at 0x7580b27574d0>: Failed to establish a new connection: [Errno 111] Connection refused'))
[2024-07-02T10:41:49.624-0400] {taskinstance.py:1206} INFO - Marking task as FAILED. dag_id=api_cuevana3_movie, task_id=execute_post_url_fastapi, run_id=scheduled__2024-07-01T00:01:45+00:00, execution_date=20240701T000145, start_date=20240702T144149, end_date=20240702T144149
[2024-07-02T10:41:49.665-0400] {standard_task_runner.py:110} ERROR - Failed to execute job 1182 for task execute_post_url_fastapi (HTTPConnectionPool(host='localhost', port=8000): Max retries exceeded with url: /scraper-url (Caused by NewConnectionError('<urllib3.connection.HTTPConnection object at 0x7580b27574d0>: Failed to establish a new connection: [Errno 111] Connection refused')); 498075)
[2024-07-02T10:41:49.729-0400] {local_task_job_runner.py:240} INFO - Task exited with return code 1
[2024-07-02T10:41:49.753-0400] {taskinstance.py:3503} INFO - 0 downstream tasks scheduled from follow-on schedule check
[2024-07-02T10:41:49.786-0400] {local_task_job_runner.py:222} INFO - ::endgroup::
[2024-07-02T10:58:20.873-0400] {local_task_job_runner.py:120} INFO - ::group::Pre task execution logs
[2024-07-02T10:58:20.888-0400] {taskinstance.py:2076} INFO - Dependencies all met for dep_context=non-requeueable deps ti=<TaskInstance: api_cuevana3_movie.execute_post_url_fastapi scheduled__2024-07-01T00:01:45+00:00 [queued]>
[2024-07-02T10:58:20.892-0400] {taskinstance.py:2076} INFO - Dependencies all met for dep_context=requeueable deps ti=<TaskInstance: api_cuevana3_movie.execute_post_url_fastapi scheduled__2024-07-01T00:01:45+00:00 [queued]>
[2024-07-02T10:58:20.893-0400] {taskinstance.py:2306} INFO - Starting attempt 1 of 1
[2024-07-02T10:58:20.923-0400] {taskinstance.py:2330} INFO - Executing <Task(PythonOperator): execute_post_url_fastapi> on 2024-07-01 00:01:45+00:00
[2024-07-02T10:58:20.928-0400] {standard_task_runner.py:63} INFO - Started process 501183 to run task
[2024-07-02T10:58:20.931-0400] {standard_task_runner.py:90} INFO - Running: ['airflow', 'tasks', 'run', 'api_cuevana3_movie', 'execute_post_url_fastapi', 'scheduled__2024-07-01T00:01:45+00:00', '--job-id', '1336', '--raw', '--subdir', 'DAGS_FOLDER/movie_recommend.py', '--cfg-path', '/tmp/tmpama9w_l4']
[2024-07-02T10:58:20.934-0400] {standard_task_runner.py:91} INFO - Job 1336: Subtask execute_post_url_fastapi
[2024-07-02T10:58:21.064-0400] {task_command.py:426} INFO - Running <TaskInstance: api_cuevana3_movie.execute_post_url_fastapi scheduled__2024-07-01T00:01:45+00:00 [running]> on host walter-VirtualBox
[2024-07-02T10:58:21.201-0400] {taskinstance.py:2648} INFO - Exporting env vars: AIRFLOW_CTX_DAG_OWNER='airflow' AIRFLOW_CTX_DAG_ID='api_cuevana3_movie' AIRFLOW_CTX_TASK_ID='execute_post_url_fastapi' AIRFLOW_CTX_EXECUTION_DATE='2024-07-01T00:01:45+00:00' AIRFLOW_CTX_TRY_NUMBER='1' AIRFLOW_CTX_DAG_RUN_ID='scheduled__2024-07-01T00:01:45+00:00'
[2024-07-02T10:58:21.202-0400] {taskinstance.py:430} INFO - ::endgroup::
[2024-07-02T10:58:21.226-0400] {taskinstance.py:441} INFO - ::group::Post task execution logs
[2024-07-02T10:58:21.226-0400] {taskinstance.py:2905} ERROR - Task failed with exception
Traceback (most recent call last):
  File "/home/walter/Documentos/rakuntentv/venv/lib/python3.12/site-packages/urllib3/connection.py", line 196, in _new_conn
    sock = connection.create_connection(
           ^^^^^^^^^^^^^^^^^^^^^^^^^^^^^
  File "/home/walter/Documentos/rakuntentv/venv/lib/python3.12/site-packages/urllib3/util/connection.py", line 85, in create_connection
    raise err
  File "/home/walter/Documentos/rakuntentv/venv/lib/python3.12/site-packages/urllib3/util/connection.py", line 73, in create_connection
    sock.connect(sa)
ConnectionRefusedError: [Errno 111] Connection refused

The above exception was the direct cause of the following exception:

Traceback (most recent call last):
  File "/home/walter/Documentos/rakuntentv/venv/lib/python3.12/site-packages/urllib3/connectionpool.py", line 789, in urlopen
    response = self._make_request(
               ^^^^^^^^^^^^^^^^^^^
  File "/home/walter/Documentos/rakuntentv/venv/lib/python3.12/site-packages/urllib3/connectionpool.py", line 495, in _make_request
    conn.request(
  File "/home/walter/Documentos/rakuntentv/venv/lib/python3.12/site-packages/urllib3/connection.py", line 398, in request
    self.endheaders()
  File "/usr/lib/python3.12/http/client.py", line 1331, in endheaders
    self._send_output(message_body, encode_chunked=encode_chunked)
  File "/usr/lib/python3.12/http/client.py", line 1091, in _send_output
    self.send(msg)
  File "/usr/lib/python3.12/http/client.py", line 1035, in send
    self.connect()
  File "/home/walter/Documentos/rakuntentv/venv/lib/python3.12/site-packages/urllib3/connection.py", line 236, in connect
    self.sock = self._new_conn()
                ^^^^^^^^^^^^^^^^
  File "/home/walter/Documentos/rakuntentv/venv/lib/python3.12/site-packages/urllib3/connection.py", line 211, in _new_conn
    raise NewConnectionError(
urllib3.exceptions.NewConnectionError: <urllib3.connection.HTTPConnection object at 0x743cd9704dd0>: Failed to establish a new connection: [Errno 111] Connection refused

The above exception was the direct cause of the following exception:

Traceback (most recent call last):
  File "/home/walter/Documentos/rakuntentv/venv/lib/python3.12/site-packages/requests/adapters.py", line 667, in send
    resp = conn.urlopen(
           ^^^^^^^^^^^^^
  File "/home/walter/Documentos/rakuntentv/venv/lib/python3.12/site-packages/urllib3/connectionpool.py", line 843, in urlopen
    retries = retries.increment(
              ^^^^^^^^^^^^^^^^^^
  File "/home/walter/Documentos/rakuntentv/venv/lib/python3.12/site-packages/urllib3/util/retry.py", line 519, in increment
    raise MaxRetryError(_pool, url, reason) from reason  # type: ignore[arg-type]
    ^^^^^^^^^^^^^^^^^^^^^^^^^^^^^^^^^^^^^^^^^^^^^^^^^^^
urllib3.exceptions.MaxRetryError: HTTPConnectionPool(host='localhost', port=8000): Max retries exceeded with url: /scraper-url (Caused by NewConnectionError('<urllib3.connection.HTTPConnection object at 0x743cd9704dd0>: Failed to establish a new connection: [Errno 111] Connection refused'))

During handling of the above exception, another exception occurred:

Traceback (most recent call last):
  File "/home/walter/Documentos/rakuntentv/venv/lib/python3.12/site-packages/airflow/models/taskinstance.py", line 465, in _execute_task
    result = _execute_callable(context=context, **execute_callable_kwargs)
             ^^^^^^^^^^^^^^^^^^^^^^^^^^^^^^^^^^^^^^^^^^^^^^^^^^^^^^^^^^^^^
  File "/home/walter/Documentos/rakuntentv/venv/lib/python3.12/site-packages/airflow/models/taskinstance.py", line 432, in _execute_callable
    return execute_callable(context=context, **execute_callable_kwargs)
           ^^^^^^^^^^^^^^^^^^^^^^^^^^^^^^^^^^^^^^^^^^^^^^^^^^^^^^^^^^^^
  File "/home/walter/Documentos/rakuntentv/venv/lib/python3.12/site-packages/airflow/models/baseoperator.py", line 401, in wrapper
    return func(self, *args, **kwargs)
           ^^^^^^^^^^^^^^^^^^^^^^^^^^^
  File "/home/walter/Documentos/rakuntentv/venv/lib/python3.12/site-packages/airflow/operators/python.py", line 235, in execute
    return_value = self.execute_callable()
                   ^^^^^^^^^^^^^^^^^^^^^^^
  File "/home/walter/Documentos/rakuntentv/venv/lib/python3.12/site-packages/airflow/operators/python.py", line 252, in execute_callable
    return self.python_callable(*self.op_args, **self.op_kwargs)
           ^^^^^^^^^^^^^^^^^^^^^^^^^^^^^^^^^^^^^^^^^^^^^^^^^^^^^
  File "/home/walter/Documentos/rakuntentv/airflow/dags/movie_recommend.py", line 19, in execute_post_url_fastapi
    response = requests.post(api_url)
               ^^^^^^^^^^^^^^^^^^^^^^
  File "/home/walter/Documentos/rakuntentv/venv/lib/python3.12/site-packages/requests/api.py", line 115, in post
    return request("post", url, data=data, json=json, **kwargs)
           ^^^^^^^^^^^^^^^^^^^^^^^^^^^^^^^^^^^^^^^^^^^^^^^^^^^^
  File "/home/walter/Documentos/rakuntentv/venv/lib/python3.12/site-packages/requests/api.py", line 59, in request
    return session.request(method=method, url=url, **kwargs)
           ^^^^^^^^^^^^^^^^^^^^^^^^^^^^^^^^^^^^^^^^^^^^^^^^^
  File "/home/walter/Documentos/rakuntentv/venv/lib/python3.12/site-packages/requests/sessions.py", line 589, in request
    resp = self.send(prep, **send_kwargs)
           ^^^^^^^^^^^^^^^^^^^^^^^^^^^^^^
  File "/home/walter/Documentos/rakuntentv/venv/lib/python3.12/site-packages/requests/sessions.py", line 703, in send
    r = adapter.send(request, **kwargs)
        ^^^^^^^^^^^^^^^^^^^^^^^^^^^^^^^
  File "/home/walter/Documentos/rakuntentv/venv/lib/python3.12/site-packages/requests/adapters.py", line 700, in send
    raise ConnectionError(e, request=request)
requests.exceptions.ConnectionError: HTTPConnectionPool(host='localhost', port=8000): Max retries exceeded with url: /scraper-url (Caused by NewConnectionError('<urllib3.connection.HTTPConnection object at 0x743cd9704dd0>: Failed to establish a new connection: [Errno 111] Connection refused'))
[2024-07-02T10:58:21.279-0400] {taskinstance.py:1206} INFO - Marking task as FAILED. dag_id=api_cuevana3_movie, task_id=execute_post_url_fastapi, run_id=scheduled__2024-07-01T00:01:45+00:00, execution_date=20240701T000145, start_date=20240702T145820, end_date=20240702T145821
[2024-07-02T10:58:21.327-0400] {standard_task_runner.py:110} ERROR - Failed to execute job 1336 for task execute_post_url_fastapi (HTTPConnectionPool(host='localhost', port=8000): Max retries exceeded with url: /scraper-url (Caused by NewConnectionError('<urllib3.connection.HTTPConnection object at 0x743cd9704dd0>: Failed to establish a new connection: [Errno 111] Connection refused')); 501183)
[2024-07-02T10:58:21.375-0400] {local_task_job_runner.py:240} INFO - Task exited with return code 1
[2024-07-02T10:58:21.436-0400] {taskinstance.py:3503} INFO - 0 downstream tasks scheduled from follow-on schedule check
[2024-07-02T10:58:21.463-0400] {local_task_job_runner.py:222} INFO - ::endgroup::
