[2024-07-01T23:53:31.169-0400] {local_task_job_runner.py:120} INFO - ::group::Pre task execution logs
[2024-07-01T23:53:31.186-0400] {taskinstance.py:2076} INFO - Dependencies all met for dep_context=non-requeueable deps ti=<TaskInstance: api_cuevana3_movie.execute_post_details_fasapi scheduled__2024-07-01T00:00:45+00:00 [queued]>
[2024-07-01T23:53:31.202-0400] {taskinstance.py:2076} INFO - Dependencies all met for dep_context=requeueable deps ti=<TaskInstance: api_cuevana3_movie.execute_post_details_fasapi scheduled__2024-07-01T00:00:45+00:00 [queued]>
[2024-07-01T23:53:31.205-0400] {taskinstance.py:2306} INFO - Starting attempt 1 of 1
[2024-07-01T23:53:31.246-0400] {taskinstance.py:2330} INFO - Executing <Task(PythonOperator): execute_post_details_fasapi> on 2024-07-01 00:00:45+00:00
[2024-07-01T23:53:31.267-0400] {standard_task_runner.py:63} INFO - Started process 465777 to run task
[2024-07-01T23:53:31.272-0400] {standard_task_runner.py:90} INFO - Running: ['airflow', 'tasks', 'run', 'api_cuevana3_movie', 'execute_post_details_fasapi', 'scheduled__2024-07-01T00:00:45+00:00', '--job-id', '928', '--raw', '--subdir', 'DAGS_FOLDER/movie_recommend.py', '--cfg-path', '/tmp/tmp56qt3r0x']
[2024-07-01T23:53:31.273-0400] {standard_task_runner.py:91} INFO - Job 928: Subtask execute_post_details_fasapi
[2024-07-01T23:53:31.311-0400] {task_command.py:426} INFO - Running <TaskInstance: api_cuevana3_movie.execute_post_details_fasapi scheduled__2024-07-01T00:00:45+00:00 [running]> on host walter-VirtualBox
[2024-07-01T23:53:31.445-0400] {taskinstance.py:2648} INFO - Exporting env vars: AIRFLOW_CTX_DAG_OWNER='airflow' AIRFLOW_CTX_DAG_ID='api_cuevana3_movie' AIRFLOW_CTX_TASK_ID='execute_post_details_fasapi' AIRFLOW_CTX_EXECUTION_DATE='2024-07-01T00:00:45+00:00' AIRFLOW_CTX_TRY_NUMBER='1' AIRFLOW_CTX_DAG_RUN_ID='scheduled__2024-07-01T00:00:45+00:00'
[2024-07-01T23:53:31.446-0400] {taskinstance.py:430} INFO - ::endgroup::
[2024-07-01T23:54:01.594-0400] {local_task_job_runner.py:310} WARNING - State of this instance has been externally set to None. Terminating instance.
[2024-07-01T23:54:01.595-0400] {local_task_job_runner.py:222} INFO - ::endgroup::
[2024-07-01T23:54:01.606-0400] {process_utils.py:132} INFO - Sending 15 to group 465777. PIDs of all processes in the group: [465777]
[2024-07-01T23:54:01.606-0400] {process_utils.py:87} INFO - Sending the signal 15 to group 465777
[2024-07-01T23:54:01.625-0400] {taskinstance.py:2611} ERROR - Received SIGTERM. Terminating subprocesses.
[2024-07-01T23:54:01.640-0400] {taskinstance.py:441} INFO - ::group::Post task execution logs
[2024-07-01T23:54:01.646-0400] {taskinstance.py:2905} ERROR - Task failed with exception
Traceback (most recent call last):
  File "/home/walter/Documentos/rakuntentv/venv/lib/python3.12/site-packages/airflow/models/taskinstance.py", line 465, in _execute_task
    result = _execute_callable(context=context, **execute_callable_kwargs)
             ^^^^^^^^^^^^^^^^^^^^^^^^^^^^^^^^^^^^^^^^^^^^^^^^^^^^^^^^^^^^^
  File "/home/walter/Documentos/rakuntentv/venv/lib/python3.12/site-packages/airflow/models/taskinstance.py", line 432, in _execute_callable
    return execute_callable(context=context, **execute_callable_kwargs)
           ^^^^^^^^^^^^^^^^^^^^^^^^^^^^^^^^^^^^^^^^^^^^^^^^^^^^^^^^^^^^
  File "/home/walter/Documentos/rakuntentv/venv/lib/python3.12/site-packages/airflow/models/baseoperator.py", line 401, in wrapper
    return func(self, *args, **kwargs)
           ^^^^^^^^^^^^^^^^^^^^^^^^^^^
  File "/home/walter/Documentos/rakuntentv/venv/lib/python3.12/site-packages/airflow/operators/python.py", line 235, in execute
    return_value = self.execute_callable()
                   ^^^^^^^^^^^^^^^^^^^^^^^
  File "/home/walter/Documentos/rakuntentv/venv/lib/python3.12/site-packages/airflow/operators/python.py", line 252, in execute_callable
    return self.python_callable(*self.op_args, **self.op_kwargs)
           ^^^^^^^^^^^^^^^^^^^^^^^^^^^^^^^^^^^^^^^^^^^^^^^^^^^^^
  File "/home/walter/Documentos/rakuntentv/airflow/dags/movie_recommend.py", line 57, in execute_post_details_fasapi
    response = requests.post(api_url)
               ^^^^^^^^^^^^^^^^^^^^^^
  File "/home/walter/Documentos/rakuntentv/venv/lib/python3.12/site-packages/requests/api.py", line 115, in post
    return request("post", url, data=data, json=json, **kwargs)
           ^^^^^^^^^^^^^^^^^^^^^^^^^^^^^^^^^^^^^^^^^^^^^^^^^^^^
  File "/home/walter/Documentos/rakuntentv/venv/lib/python3.12/site-packages/requests/api.py", line 59, in request
    return session.request(method=method, url=url, **kwargs)
           ^^^^^^^^^^^^^^^^^^^^^^^^^^^^^^^^^^^^^^^^^^^^^^^^^
  File "/home/walter/Documentos/rakuntentv/venv/lib/python3.12/site-packages/requests/sessions.py", line 589, in request
    resp = self.send(prep, **send_kwargs)
           ^^^^^^^^^^^^^^^^^^^^^^^^^^^^^^
  File "/home/walter/Documentos/rakuntentv/venv/lib/python3.12/site-packages/requests/sessions.py", line 703, in send
    r = adapter.send(request, **kwargs)
        ^^^^^^^^^^^^^^^^^^^^^^^^^^^^^^^
  File "/home/walter/Documentos/rakuntentv/venv/lib/python3.12/site-packages/requests/adapters.py", line 667, in send
    resp = conn.urlopen(
           ^^^^^^^^^^^^^
  File "/home/walter/Documentos/rakuntentv/venv/lib/python3.12/site-packages/urllib3/connectionpool.py", line 789, in urlopen
    response = self._make_request(
               ^^^^^^^^^^^^^^^^^^^
  File "/home/walter/Documentos/rakuntentv/venv/lib/python3.12/site-packages/urllib3/connectionpool.py", line 536, in _make_request
    response = conn.getresponse()
               ^^^^^^^^^^^^^^^^^^
  File "/home/walter/Documentos/rakuntentv/venv/lib/python3.12/site-packages/urllib3/connection.py", line 464, in getresponse
    httplib_response = super().getresponse()
                       ^^^^^^^^^^^^^^^^^^^^^
  File "/usr/lib/python3.12/http/client.py", line 1428, in getresponse
    response.begin()
  File "/usr/lib/python3.12/http/client.py", line 331, in begin
    version, status, reason = self._read_status()
                              ^^^^^^^^^^^^^^^^^^^
  File "/usr/lib/python3.12/http/client.py", line 292, in _read_status
    line = str(self.fp.readline(_MAXLINE + 1), "iso-8859-1")
               ^^^^^^^^^^^^^^^^^^^^^^^^^^^^^^
  File "/usr/lib/python3.12/socket.py", line 707, in readinto
    return self._sock.recv_into(b)
           ^^^^^^^^^^^^^^^^^^^^^^^
  File "/home/walter/Documentos/rakuntentv/venv/lib/python3.12/site-packages/airflow/models/taskinstance.py", line 2613, in signal_handler
    raise AirflowTaskTerminated("Task received SIGTERM signal")
airflow.exceptions.AirflowTaskTerminated: Task received SIGTERM signal
[2024-07-01T23:54:01.719-0400] {taskinstance.py:1206} INFO - Marking task as FAILED. dag_id=api_cuevana3_movie, task_id=execute_post_details_fasapi, run_id=scheduled__2024-07-01T00:00:45+00:00, execution_date=20240701T000045, start_date=20240702T035331, end_date=20240702T035401
[2024-07-01T23:54:01.732-0400] {standard_task_runner.py:110} ERROR - Failed to execute job 928 for task execute_post_details_fasapi ((sqlite3.IntegrityError) FOREIGN KEY constraint failed
[SQL: INSERT INTO task_fail (task_id, dag_id, run_id, map_index, start_date, end_date, duration) VALUES (?, ?, ?, ?, ?, ?, ?)]
[parameters: ('execute_post_details_fasapi', 'api_cuevana3_movie', 'scheduled__2024-07-01T00:00:45+00:00', -1, '2024-07-02 03:53:31.188071', '2024-07-02 03:54:01.719218', 30)]
(Background on this error at: https://sqlalche.me/e/14/gkpj); 465777)
[2024-07-01T23:54:01.763-0400] {process_utils.py:80} INFO - Process psutil.Process(pid=465777, status='terminated', exitcode=1, started='23:53:30') (465777) terminated with exit code 1
[2024-07-01T23:59:16.316-0400] {local_task_job_runner.py:120} INFO - ::group::Pre task execution logs
[2024-07-01T23:59:16.342-0400] {taskinstance.py:2076} INFO - Dependencies all met for dep_context=non-requeueable deps ti=<TaskInstance: api_cuevana3_movie.execute_post_details_fasapi scheduled__2024-07-01T00:00:45+00:00 [queued]>
[2024-07-01T23:59:16.361-0400] {taskinstance.py:2076} INFO - Dependencies all met for dep_context=requeueable deps ti=<TaskInstance: api_cuevana3_movie.execute_post_details_fasapi scheduled__2024-07-01T00:00:45+00:00 [queued]>
[2024-07-01T23:59:16.362-0400] {taskinstance.py:2306} INFO - Starting attempt 1 of 1
[2024-07-01T23:59:16.424-0400] {taskinstance.py:2330} INFO - Executing <Task(PythonOperator): execute_post_details_fasapi> on 2024-07-01 00:00:45+00:00
[2024-07-01T23:59:16.437-0400] {standard_task_runner.py:63} INFO - Started process 470006 to run task
[2024-07-01T23:59:16.441-0400] {standard_task_runner.py:90} INFO - Running: ['airflow', 'tasks', 'run', 'api_cuevana3_movie', 'execute_post_details_fasapi', 'scheduled__2024-07-01T00:00:45+00:00', '--job-id', '940', '--raw', '--subdir', 'DAGS_FOLDER/movie_recommend.py', '--cfg-path', '/tmp/tmpivw39948']
[2024-07-01T23:59:16.452-0400] {standard_task_runner.py:91} INFO - Job 940: Subtask execute_post_details_fasapi
[2024-07-01T23:59:16.571-0400] {task_command.py:426} INFO - Running <TaskInstance: api_cuevana3_movie.execute_post_details_fasapi scheduled__2024-07-01T00:00:45+00:00 [running]> on host walter-VirtualBox
[2024-07-01T23:59:16.679-0400] {taskinstance.py:2648} INFO - Exporting env vars: AIRFLOW_CTX_DAG_OWNER='airflow' AIRFLOW_CTX_DAG_ID='api_cuevana3_movie' AIRFLOW_CTX_TASK_ID='execute_post_details_fasapi' AIRFLOW_CTX_EXECUTION_DATE='2024-07-01T00:00:45+00:00' AIRFLOW_CTX_TRY_NUMBER='1' AIRFLOW_CTX_DAG_RUN_ID='scheduled__2024-07-01T00:00:45+00:00'
[2024-07-01T23:59:16.680-0400] {taskinstance.py:430} INFO - ::endgroup::
[2024-07-01T23:59:47.818-0400] {taskinstance.py:441} INFO - ::group::Post task execution logs
[2024-07-01T23:59:47.819-0400] {taskinstance.py:2905} ERROR - Task failed with exception
Traceback (most recent call last):
  File "/home/walter/Documentos/rakuntentv/venv/lib/python3.12/site-packages/urllib3/connectionpool.py", line 789, in urlopen
    response = self._make_request(
               ^^^^^^^^^^^^^^^^^^^
  File "/home/walter/Documentos/rakuntentv/venv/lib/python3.12/site-packages/urllib3/connectionpool.py", line 536, in _make_request
    response = conn.getresponse()
               ^^^^^^^^^^^^^^^^^^
  File "/home/walter/Documentos/rakuntentv/venv/lib/python3.12/site-packages/urllib3/connection.py", line 464, in getresponse
    httplib_response = super().getresponse()
                       ^^^^^^^^^^^^^^^^^^^^^
  File "/usr/lib/python3.12/http/client.py", line 1428, in getresponse
    response.begin()
  File "/usr/lib/python3.12/http/client.py", line 331, in begin
    version, status, reason = self._read_status()
                              ^^^^^^^^^^^^^^^^^^^
  File "/usr/lib/python3.12/http/client.py", line 300, in _read_status
    raise RemoteDisconnected("Remote end closed connection without"
http.client.RemoteDisconnected: Remote end closed connection without response

During handling of the above exception, another exception occurred:

Traceback (most recent call last):
  File "/home/walter/Documentos/rakuntentv/venv/lib/python3.12/site-packages/requests/adapters.py", line 667, in send
    resp = conn.urlopen(
           ^^^^^^^^^^^^^
  File "/home/walter/Documentos/rakuntentv/venv/lib/python3.12/site-packages/urllib3/connectionpool.py", line 843, in urlopen
    retries = retries.increment(
              ^^^^^^^^^^^^^^^^^^
  File "/home/walter/Documentos/rakuntentv/venv/lib/python3.12/site-packages/urllib3/util/retry.py", line 474, in increment
    raise reraise(type(error), error, _stacktrace)
          ^^^^^^^^^^^^^^^^^^^^^^^^^^^^^^^^^^^^^^^^
  File "/home/walter/Documentos/rakuntentv/venv/lib/python3.12/site-packages/urllib3/util/util.py", line 38, in reraise
    raise value.with_traceback(tb)
  File "/home/walter/Documentos/rakuntentv/venv/lib/python3.12/site-packages/urllib3/connectionpool.py", line 789, in urlopen
    response = self._make_request(
               ^^^^^^^^^^^^^^^^^^^
  File "/home/walter/Documentos/rakuntentv/venv/lib/python3.12/site-packages/urllib3/connectionpool.py", line 536, in _make_request
    response = conn.getresponse()
               ^^^^^^^^^^^^^^^^^^
  File "/home/walter/Documentos/rakuntentv/venv/lib/python3.12/site-packages/urllib3/connection.py", line 464, in getresponse
    httplib_response = super().getresponse()
                       ^^^^^^^^^^^^^^^^^^^^^
  File "/usr/lib/python3.12/http/client.py", line 1428, in getresponse
    response.begin()
  File "/usr/lib/python3.12/http/client.py", line 331, in begin
    version, status, reason = self._read_status()
                              ^^^^^^^^^^^^^^^^^^^
  File "/usr/lib/python3.12/http/client.py", line 300, in _read_status
    raise RemoteDisconnected("Remote end closed connection without"
urllib3.exceptions.ProtocolError: ('Connection aborted.', RemoteDisconnected('Remote end closed connection without response'))

During handling of the above exception, another exception occurred:

Traceback (most recent call last):
  File "/home/walter/Documentos/rakuntentv/venv/lib/python3.12/site-packages/airflow/models/taskinstance.py", line 465, in _execute_task
    result = _execute_callable(context=context, **execute_callable_kwargs)
             ^^^^^^^^^^^^^^^^^^^^^^^^^^^^^^^^^^^^^^^^^^^^^^^^^^^^^^^^^^^^^
  File "/home/walter/Documentos/rakuntentv/venv/lib/python3.12/site-packages/airflow/models/taskinstance.py", line 432, in _execute_callable
    return execute_callable(context=context, **execute_callable_kwargs)
           ^^^^^^^^^^^^^^^^^^^^^^^^^^^^^^^^^^^^^^^^^^^^^^^^^^^^^^^^^^^^
  File "/home/walter/Documentos/rakuntentv/venv/lib/python3.12/site-packages/airflow/models/baseoperator.py", line 401, in wrapper
    return func(self, *args, **kwargs)
           ^^^^^^^^^^^^^^^^^^^^^^^^^^^
  File "/home/walter/Documentos/rakuntentv/venv/lib/python3.12/site-packages/airflow/operators/python.py", line 235, in execute
    return_value = self.execute_callable()
                   ^^^^^^^^^^^^^^^^^^^^^^^
  File "/home/walter/Documentos/rakuntentv/venv/lib/python3.12/site-packages/airflow/operators/python.py", line 252, in execute_callable
    return self.python_callable(*self.op_args, **self.op_kwargs)
           ^^^^^^^^^^^^^^^^^^^^^^^^^^^^^^^^^^^^^^^^^^^^^^^^^^^^^
  File "/home/walter/Documentos/rakuntentv/airflow/dags/movie_recommend.py", line 57, in execute_post_details_fasapi
    response = requests.post(api_url)
               ^^^^^^^^^^^^^^^^^^^^^^
  File "/home/walter/Documentos/rakuntentv/venv/lib/python3.12/site-packages/requests/api.py", line 115, in post
    return request("post", url, data=data, json=json, **kwargs)
           ^^^^^^^^^^^^^^^^^^^^^^^^^^^^^^^^^^^^^^^^^^^^^^^^^^^^
  File "/home/walter/Documentos/rakuntentv/venv/lib/python3.12/site-packages/requests/api.py", line 59, in request
    return session.request(method=method, url=url, **kwargs)
           ^^^^^^^^^^^^^^^^^^^^^^^^^^^^^^^^^^^^^^^^^^^^^^^^^
  File "/home/walter/Documentos/rakuntentv/venv/lib/python3.12/site-packages/requests/sessions.py", line 589, in request
    resp = self.send(prep, **send_kwargs)
           ^^^^^^^^^^^^^^^^^^^^^^^^^^^^^^
  File "/home/walter/Documentos/rakuntentv/venv/lib/python3.12/site-packages/requests/sessions.py", line 703, in send
    r = adapter.send(request, **kwargs)
        ^^^^^^^^^^^^^^^^^^^^^^^^^^^^^^^
  File "/home/walter/Documentos/rakuntentv/venv/lib/python3.12/site-packages/requests/adapters.py", line 682, in send
    raise ConnectionError(err, request=request)
requests.exceptions.ConnectionError: ('Connection aborted.', RemoteDisconnected('Remote end closed connection without response'))
[2024-07-01T23:59:47.833-0400] {taskinstance.py:1206} INFO - Marking task as FAILED. dag_id=api_cuevana3_movie, task_id=execute_post_details_fasapi, run_id=scheduled__2024-07-01T00:00:45+00:00, execution_date=20240701T000045, start_date=20240702T035916, end_date=20240702T035947
[2024-07-01T23:59:47.880-0400] {standard_task_runner.py:110} ERROR - Failed to execute job 940 for task execute_post_details_fasapi (('Connection aborted.', RemoteDisconnected('Remote end closed connection without response')); 470006)
[2024-07-01T23:59:47.912-0400] {local_task_job_runner.py:240} INFO - Task exited with return code 1
[2024-07-01T23:59:47.957-0400] {taskinstance.py:3503} INFO - 0 downstream tasks scheduled from follow-on schedule check
[2024-07-01T23:59:48.011-0400] {local_task_job_runner.py:222} INFO - ::endgroup::
[2024-07-02T10:38:30.135-0400] {local_task_job_runner.py:120} INFO - ::group::Pre task execution logs
[2024-07-02T10:38:30.152-0400] {taskinstance.py:2076} INFO - Dependencies all met for dep_context=non-requeueable deps ti=<TaskInstance: api_cuevana3_movie.execute_post_details_fasapi scheduled__2024-07-01T00:00:45+00:00 [queued]>
[2024-07-02T10:38:30.156-0400] {taskinstance.py:2076} INFO - Dependencies all met for dep_context=requeueable deps ti=<TaskInstance: api_cuevana3_movie.execute_post_details_fasapi scheduled__2024-07-01T00:00:45+00:00 [queued]>
[2024-07-02T10:38:30.156-0400] {taskinstance.py:2306} INFO - Starting attempt 1 of 1
[2024-07-02T10:38:30.188-0400] {taskinstance.py:2330} INFO - Executing <Task(PythonOperator): execute_post_details_fasapi> on 2024-07-01 00:00:45+00:00
[2024-07-02T10:38:30.213-0400] {standard_task_runner.py:63} INFO - Started process 497021 to run task
[2024-07-02T10:38:30.239-0400] {standard_task_runner.py:90} INFO - Running: ['airflow', 'tasks', 'run', 'api_cuevana3_movie', 'execute_post_details_fasapi', 'scheduled__2024-07-01T00:00:45+00:00', '--job-id', '1168', '--raw', '--subdir', 'DAGS_FOLDER/movie_recommend.py', '--cfg-path', '/tmp/tmpslwr8cwx']
[2024-07-02T10:38:30.251-0400] {standard_task_runner.py:91} INFO - Job 1168: Subtask execute_post_details_fasapi
[2024-07-02T10:38:30.427-0400] {task_command.py:426} INFO - Running <TaskInstance: api_cuevana3_movie.execute_post_details_fasapi scheduled__2024-07-01T00:00:45+00:00 [running]> on host walter-VirtualBox
[2024-07-02T10:38:30.616-0400] {taskinstance.py:2648} INFO - Exporting env vars: AIRFLOW_CTX_DAG_OWNER='airflow' AIRFLOW_CTX_DAG_ID='api_cuevana3_movie' AIRFLOW_CTX_TASK_ID='execute_post_details_fasapi' AIRFLOW_CTX_EXECUTION_DATE='2024-07-01T00:00:45+00:00' AIRFLOW_CTX_TRY_NUMBER='1' AIRFLOW_CTX_DAG_RUN_ID='scheduled__2024-07-01T00:00:45+00:00'
[2024-07-02T10:38:30.617-0400] {taskinstance.py:430} INFO - ::endgroup::
[2024-07-02T10:39:25.821-0400] {python.py:237} INFO - Done. Returned value was: None
[2024-07-02T10:39:25.822-0400] {taskinstance.py:441} INFO - ::group::Post task execution logs
[2024-07-02T10:39:25.830-0400] {taskinstance.py:1206} INFO - Marking task as SUCCESS. dag_id=api_cuevana3_movie, task_id=execute_post_details_fasapi, run_id=scheduled__2024-07-01T00:00:45+00:00, execution_date=20240701T000045, start_date=20240702T143830, end_date=20240702T143925
[2024-07-02T10:39:25.891-0400] {local_task_job_runner.py:240} INFO - Task exited with return code 0
[2024-07-02T10:39:25.915-0400] {taskinstance.py:3503} INFO - 3 downstream tasks scheduled from follow-on schedule check
[2024-07-02T10:39:25.926-0400] {local_task_job_runner.py:222} INFO - ::endgroup::
