[2024-07-01T20:14:44.988-0400] {local_task_job_runner.py:120} INFO - ::group::Pre task execution logs
[2024-07-01T20:14:45.009-0400] {taskinstance.py:2076} INFO - Dependencies all met for dep_context=non-requeueable deps ti=<TaskInstance: api_cuevana3_movie.execute_post_details_fasapi scheduled__2024-07-01T10:00:00+00:00 [queued]>
[2024-07-01T20:14:45.021-0400] {taskinstance.py:2076} INFO - Dependencies all met for dep_context=requeueable deps ti=<TaskInstance: api_cuevana3_movie.execute_post_details_fasapi scheduled__2024-07-01T10:00:00+00:00 [queued]>
[2024-07-01T20:14:45.023-0400] {taskinstance.py:2306} INFO - Starting attempt 1 of 1
[2024-07-01T20:14:45.064-0400] {taskinstance.py:2330} INFO - Executing <Task(PythonOperator): execute_post_details_fasapi> on 2024-07-01 10:00:00+00:00
[2024-07-01T20:14:45.073-0400] {standard_task_runner.py:63} INFO - Started process 414812 to run task
[2024-07-01T20:14:45.076-0400] {standard_task_runner.py:90} INFO - Running: ['airflow', 'tasks', 'run', 'api_cuevana3_movie', 'execute_post_details_fasapi', 'scheduled__2024-07-01T10:00:00+00:00', '--job-id', '720', '--raw', '--subdir', 'DAGS_FOLDER/movie_recommend.py', '--cfg-path', '/tmp/tmp313i8lzo']
[2024-07-01T20:14:45.078-0400] {standard_task_runner.py:91} INFO - Job 720: Subtask execute_post_details_fasapi
[2024-07-01T20:14:45.126-0400] {task_command.py:426} INFO - Running <TaskInstance: api_cuevana3_movie.execute_post_details_fasapi scheduled__2024-07-01T10:00:00+00:00 [running]> on host walter-VirtualBox
[2024-07-01T20:14:45.221-0400] {taskinstance.py:2648} INFO - Exporting env vars: AIRFLOW_CTX_DAG_OWNER='airflow' AIRFLOW_CTX_DAG_ID='api_cuevana3_movie' AIRFLOW_CTX_TASK_ID='execute_post_details_fasapi' AIRFLOW_CTX_EXECUTION_DATE='2024-07-01T10:00:00+00:00' AIRFLOW_CTX_TRY_NUMBER='1' AIRFLOW_CTX_DAG_RUN_ID='scheduled__2024-07-01T10:00:00+00:00'
[2024-07-01T20:14:45.223-0400] {taskinstance.py:430} INFO - ::endgroup::
[2024-07-01T20:14:45.281-0400] {taskinstance.py:441} INFO - ::group::Post task execution logs
[2024-07-01T20:14:45.285-0400] {taskinstance.py:2905} ERROR - Task failed with exception
Traceback (most recent call last):
  File "/home/walter/Documentos/rakuntentv/venv/lib/python3.12/site-packages/urllib3/connection.py", line 196, in _new_conn
    sock = connection.create_connection(
           ^^^^^^^^^^^^^^^^^^^^^^^^^^^^^
  File "/home/walter/Documentos/rakuntentv/venv/lib/python3.12/site-packages/urllib3/util/connection.py", line 85, in create_connection
    raise err
  File "/home/walter/Documentos/rakuntentv/venv/lib/python3.12/site-packages/urllib3/util/connection.py", line 73, in create_connection
    sock.connect(sa)
ConnectionRefusedError: [Errno 111] Connection refused

The above exception was the direct cause of the following exception:

Traceback (most recent call last):
  File "/home/walter/Documentos/rakuntentv/venv/lib/python3.12/site-packages/urllib3/connectionpool.py", line 789, in urlopen
    response = self._make_request(
               ^^^^^^^^^^^^^^^^^^^
  File "/home/walter/Documentos/rakuntentv/venv/lib/python3.12/site-packages/urllib3/connectionpool.py", line 495, in _make_request
    conn.request(
  File "/home/walter/Documentos/rakuntentv/venv/lib/python3.12/site-packages/urllib3/connection.py", line 398, in request
    self.endheaders()
  File "/usr/lib/python3.12/http/client.py", line 1331, in endheaders
    self._send_output(message_body, encode_chunked=encode_chunked)
  File "/usr/lib/python3.12/http/client.py", line 1091, in _send_output
    self.send(msg)
  File "/usr/lib/python3.12/http/client.py", line 1035, in send
    self.connect()
  File "/home/walter/Documentos/rakuntentv/venv/lib/python3.12/site-packages/urllib3/connection.py", line 236, in connect
    self.sock = self._new_conn()
                ^^^^^^^^^^^^^^^^
  File "/home/walter/Documentos/rakuntentv/venv/lib/python3.12/site-packages/urllib3/connection.py", line 211, in _new_conn
    raise NewConnectionError(
urllib3.exceptions.NewConnectionError: <urllib3.connection.HTTPConnection object at 0x75b13fab7590>: Failed to establish a new connection: [Errno 111] Connection refused

The above exception was the direct cause of the following exception:

Traceback (most recent call last):
  File "/home/walter/Documentos/rakuntentv/venv/lib/python3.12/site-packages/requests/adapters.py", line 667, in send
    resp = conn.urlopen(
           ^^^^^^^^^^^^^
  File "/home/walter/Documentos/rakuntentv/venv/lib/python3.12/site-packages/urllib3/connectionpool.py", line 843, in urlopen
    retries = retries.increment(
              ^^^^^^^^^^^^^^^^^^
  File "/home/walter/Documentos/rakuntentv/venv/lib/python3.12/site-packages/urllib3/util/retry.py", line 519, in increment
    raise MaxRetryError(_pool, url, reason) from reason  # type: ignore[arg-type]
    ^^^^^^^^^^^^^^^^^^^^^^^^^^^^^^^^^^^^^^^^^^^^^^^^^^^
urllib3.exceptions.MaxRetryError: HTTPConnectionPool(host='localhost', port=8000): Max retries exceeded with url: /scraper-movies-details (Caused by NewConnectionError('<urllib3.connection.HTTPConnection object at 0x75b13fab7590>: Failed to establish a new connection: [Errno 111] Connection refused'))

During handling of the above exception, another exception occurred:

Traceback (most recent call last):
  File "/home/walter/Documentos/rakuntentv/venv/lib/python3.12/site-packages/airflow/models/taskinstance.py", line 465, in _execute_task
    result = _execute_callable(context=context, **execute_callable_kwargs)
             ^^^^^^^^^^^^^^^^^^^^^^^^^^^^^^^^^^^^^^^^^^^^^^^^^^^^^^^^^^^^^
  File "/home/walter/Documentos/rakuntentv/venv/lib/python3.12/site-packages/airflow/models/taskinstance.py", line 432, in _execute_callable
    return execute_callable(context=context, **execute_callable_kwargs)
           ^^^^^^^^^^^^^^^^^^^^^^^^^^^^^^^^^^^^^^^^^^^^^^^^^^^^^^^^^^^^
  File "/home/walter/Documentos/rakuntentv/venv/lib/python3.12/site-packages/airflow/models/baseoperator.py", line 401, in wrapper
    return func(self, *args, **kwargs)
           ^^^^^^^^^^^^^^^^^^^^^^^^^^^
  File "/home/walter/Documentos/rakuntentv/venv/lib/python3.12/site-packages/airflow/operators/python.py", line 235, in execute
    return_value = self.execute_callable()
                   ^^^^^^^^^^^^^^^^^^^^^^^
  File "/home/walter/Documentos/rakuntentv/venv/lib/python3.12/site-packages/airflow/operators/python.py", line 252, in execute_callable
    return self.python_callable(*self.op_args, **self.op_kwargs)
           ^^^^^^^^^^^^^^^^^^^^^^^^^^^^^^^^^^^^^^^^^^^^^^^^^^^^^
  File "/home/walter/Documentos/rakuntentv/airflow/dags/movie_recommend.py", line 60, in execute_post_details_fasapi
    response = requests.post(api_url)
               ^^^^^^^^^^^^^^^^^^^^^^
  File "/home/walter/Documentos/rakuntentv/venv/lib/python3.12/site-packages/requests/api.py", line 115, in post
    return request("post", url, data=data, json=json, **kwargs)
           ^^^^^^^^^^^^^^^^^^^^^^^^^^^^^^^^^^^^^^^^^^^^^^^^^^^^
  File "/home/walter/Documentos/rakuntentv/venv/lib/python3.12/site-packages/requests/api.py", line 59, in request
    return session.request(method=method, url=url, **kwargs)
           ^^^^^^^^^^^^^^^^^^^^^^^^^^^^^^^^^^^^^^^^^^^^^^^^^
  File "/home/walter/Documentos/rakuntentv/venv/lib/python3.12/site-packages/requests/sessions.py", line 589, in request
    resp = self.send(prep, **send_kwargs)
           ^^^^^^^^^^^^^^^^^^^^^^^^^^^^^^
  File "/home/walter/Documentos/rakuntentv/venv/lib/python3.12/site-packages/requests/sessions.py", line 703, in send
    r = adapter.send(request, **kwargs)
        ^^^^^^^^^^^^^^^^^^^^^^^^^^^^^^^
  File "/home/walter/Documentos/rakuntentv/venv/lib/python3.12/site-packages/requests/adapters.py", line 700, in send
    raise ConnectionError(e, request=request)
requests.exceptions.ConnectionError: HTTPConnectionPool(host='localhost', port=8000): Max retries exceeded with url: /scraper-movies-details (Caused by NewConnectionError('<urllib3.connection.HTTPConnection object at 0x75b13fab7590>: Failed to establish a new connection: [Errno 111] Connection refused'))
[2024-07-01T20:14:45.291-0400] {taskinstance.py:1206} INFO - Marking task as FAILED. dag_id=api_cuevana3_movie, task_id=execute_post_details_fasapi, run_id=scheduled__2024-07-01T10:00:00+00:00, execution_date=20240701T100000, start_date=20240702T001445, end_date=20240702T001445
[2024-07-01T20:14:45.326-0400] {standard_task_runner.py:110} ERROR - Failed to execute job 720 for task execute_post_details_fasapi (HTTPConnectionPool(host='localhost', port=8000): Max retries exceeded with url: /scraper-movies-details (Caused by NewConnectionError('<urllib3.connection.HTTPConnection object at 0x75b13fab7590>: Failed to establish a new connection: [Errno 111] Connection refused')); 414812)
[2024-07-01T20:14:45.348-0400] {local_task_job_runner.py:240} INFO - Task exited with return code 1
[2024-07-01T20:14:45.371-0400] {taskinstance.py:3503} INFO - 0 downstream tasks scheduled from follow-on schedule check
[2024-07-01T20:14:45.389-0400] {local_task_job_runner.py:222} INFO - ::endgroup::
[2024-07-01T23:15:38.495-0400] {local_task_job_runner.py:120} INFO - ::group::Pre task execution logs
[2024-07-01T23:15:38.513-0400] {taskinstance.py:2076} INFO - Dependencies all met for dep_context=non-requeueable deps ti=<TaskInstance: api_cuevana3_movie.execute_post_details_fasapi scheduled__2024-07-01T10:00:00+00:00 [queued]>
[2024-07-01T23:15:38.519-0400] {taskinstance.py:2076} INFO - Dependencies all met for dep_context=requeueable deps ti=<TaskInstance: api_cuevana3_movie.execute_post_details_fasapi scheduled__2024-07-01T10:00:00+00:00 [queued]>
[2024-07-01T23:15:38.519-0400] {taskinstance.py:2306} INFO - Starting attempt 1 of 1
[2024-07-01T23:15:38.533-0400] {taskinstance.py:2330} INFO - Executing <Task(PythonOperator): execute_post_details_fasapi> on 2024-07-01 10:00:00+00:00
[2024-07-01T23:15:38.538-0400] {standard_task_runner.py:63} INFO - Started process 449167 to run task
[2024-07-01T23:15:38.540-0400] {standard_task_runner.py:90} INFO - Running: ['airflow', 'tasks', 'run', 'api_cuevana3_movie', 'execute_post_details_fasapi', 'scheduled__2024-07-01T10:00:00+00:00', '--job-id', '852', '--raw', '--subdir', 'DAGS_FOLDER/movie_recommend.py', '--cfg-path', '/tmp/tmp7xgqqcl4']
[2024-07-01T23:15:38.542-0400] {standard_task_runner.py:91} INFO - Job 852: Subtask execute_post_details_fasapi
[2024-07-01T23:15:38.578-0400] {task_command.py:426} INFO - Running <TaskInstance: api_cuevana3_movie.execute_post_details_fasapi scheduled__2024-07-01T10:00:00+00:00 [running]> on host walter-VirtualBox
[2024-07-01T23:15:38.669-0400] {taskinstance.py:2648} INFO - Exporting env vars: AIRFLOW_CTX_DAG_OWNER='airflow' AIRFLOW_CTX_DAG_ID='api_cuevana3_movie' AIRFLOW_CTX_TASK_ID='execute_post_details_fasapi' AIRFLOW_CTX_EXECUTION_DATE='2024-07-01T10:00:00+00:00' AIRFLOW_CTX_TRY_NUMBER='1' AIRFLOW_CTX_DAG_RUN_ID='scheduled__2024-07-01T10:00:00+00:00'
[2024-07-01T23:15:38.669-0400] {taskinstance.py:430} INFO - ::endgroup::
[2024-07-01T23:16:31.591-0400] {logging_mixin.py:188} INFO - Scraping movie details running successfully
[2024-07-01T23:16:31.621-0400] {logging_mixin.py:188} INFO - {"image_url": "https://i0.wp.com/www.themoviedb.org/t/p/w185/3HoBhPg6T5st6K09QfZh4lGB0hz.jpg", "title": "La academia del Sr. Kleks", "rating": 6.1, "duration": "2h 10m", "year": "2024", "quality": "HD", "description": "Ver la academia del sr. kleks Cuevana3.En busca de su padre, que ha desaparecido, una adolescente aparentemente normal acepta asistir a una universidad m\u00e1gica dirigida por un profesor exc\u00e9ntrico, el Sr. Kleks.", "genre": ["Fantas\u00eda", "Aventura", "Familia"], "country": "Bulgaria", "director": "Maciej Kawulski", "actors": ["Antonina Litwiniak,", "Tomasz Kot,", "Piotr Fronczewski,", "Sebastian Stankiewicz,", "Agnieszka Grochowska,", "Danuta Stenka,", "Daniel Walasek,", "Konrad Repi\u0144ski,", "Igor Fernandez-Kowalczyk,", "Apolonia Ga\u0142\u0119ska,", "Daria Kalinchuk,", "Amelia Luty\u0144ska,", "Enkhkhangaluun Byambadul,", "Jan Makowski,", "Jana Jachimek,", "Liu Sitkowska,", "Maria Al Tlfah,", "Dima Al Tlfah,", "Nikodem Adamski,", "Julian Mr\u00f3wczy\u0144ski,", "Adam Panikowski,"], "views": 50}
[2024-07-01T23:16:31.640-0400] {python.py:237} INFO - Done. Returned value was: {"image_url": "https://i0.wp.com/www.themoviedb.org/t/p/w185/3HoBhPg6T5st6K09QfZh4lGB0hz.jpg", "title": "La academia del Sr. Kleks", "rating": 6.1, "duration": "2h 10m", "year": "2024", "quality": "HD", "description": "Ver la academia del sr. kleks Cuevana3.En busca de su padre, que ha desaparecido, una adolescente aparentemente normal acepta asistir a una universidad m\u00e1gica dirigida por un profesor exc\u00e9ntrico, el Sr. Kleks.", "genre": ["Fantas\u00eda", "Aventura", "Familia"], "country": "Bulgaria", "director": "Maciej Kawulski", "actors": ["Antonina Litwiniak,", "Tomasz Kot,", "Piotr Fronczewski,", "Sebastian Stankiewicz,", "Agnieszka Grochowska,", "Danuta Stenka,", "Daniel Walasek,", "Konrad Repi\u0144ski,", "Igor Fernandez-Kowalczyk,", "Apolonia Ga\u0142\u0119ska,", "Daria Kalinchuk,", "Amelia Luty\u0144ska,", "Enkhkhangaluun Byambadul,", "Jan Makowski,", "Jana Jachimek,", "Liu Sitkowska,", "Maria Al Tlfah,", "Dima Al Tlfah,", "Nikodem Adamski,", "Julian Mr\u00f3wczy\u0144ski,", "Adam Panikowski,"], "views": 50}
[2024-07-01T23:16:31.641-0400] {taskinstance.py:441} INFO - ::group::Post task execution logs
[2024-07-01T23:16:31.694-0400] {taskinstance.py:1206} INFO - Marking task as SUCCESS. dag_id=api_cuevana3_movie, task_id=execute_post_details_fasapi, run_id=scheduled__2024-07-01T10:00:00+00:00, execution_date=20240701T100000, start_date=20240702T031538, end_date=20240702T031631
[2024-07-01T23:16:31.769-0400] {local_task_job_runner.py:240} INFO - Task exited with return code 0
[2024-07-01T23:16:31.783-0400] {taskinstance.py:3503} INFO - 0 downstream tasks scheduled from follow-on schedule check
[2024-07-01T23:16:31.784-0400] {local_task_job_runner.py:222} INFO - ::endgroup::
