[2024-07-01T11:06:16.456-0400] {local_task_job_runner.py:120} INFO - ::group::Pre task execution logs
[2024-07-01T11:06:16.472-0400] {taskinstance.py:2076} INFO - Dependencies all met for dep_context=non-requeueable deps ti=<TaskInstance: api_cuevana3_movie.execute_post_details_fasapi scheduled__2024-07-01T02:00:00+00:00 [queued]>
[2024-07-01T11:06:16.482-0400] {taskinstance.py:2076} INFO - Dependencies all met for dep_context=requeueable deps ti=<TaskInstance: api_cuevana3_movie.execute_post_details_fasapi scheduled__2024-07-01T02:00:00+00:00 [queued]>
[2024-07-01T11:06:16.483-0400] {taskinstance.py:2306} INFO - Starting attempt 1 of 1
[2024-07-01T11:06:16.551-0400] {taskinstance.py:2330} INFO - Executing <Task(PythonOperator): execute_post_details_fasapi> on 2024-07-01 02:00:00+00:00
[2024-07-01T11:06:16.563-0400] {standard_task_runner.py:63} INFO - Started process 381778 to run task
[2024-07-01T11:06:16.567-0400] {standard_task_runner.py:90} INFO - Running: ['airflow', 'tasks', 'run', 'api_cuevana3_movie', 'execute_post_details_fasapi', 'scheduled__2024-07-01T02:00:00+00:00', '--job-id', '653', '--raw', '--subdir', 'DAGS_FOLDER/movie_recommend.py', '--cfg-path', '/tmp/tmp7dh2s9xf']
[2024-07-01T11:06:16.569-0400] {standard_task_runner.py:91} INFO - Job 653: Subtask execute_post_details_fasapi
[2024-07-01T11:06:16.609-0400] {task_command.py:426} INFO - Running <TaskInstance: api_cuevana3_movie.execute_post_details_fasapi scheduled__2024-07-01T02:00:00+00:00 [running]> on host walter-VirtualBox
[2024-07-01T11:06:16.723-0400] {taskinstance.py:2648} INFO - Exporting env vars: AIRFLOW_CTX_DAG_OWNER='airflow' AIRFLOW_CTX_DAG_ID='api_cuevana3_movie' AIRFLOW_CTX_TASK_ID='execute_post_details_fasapi' AIRFLOW_CTX_EXECUTION_DATE='2024-07-01T02:00:00+00:00' AIRFLOW_CTX_TRY_NUMBER='1' AIRFLOW_CTX_DAG_RUN_ID='scheduled__2024-07-01T02:00:00+00:00'
[2024-07-01T11:06:16.724-0400] {taskinstance.py:430} INFO - ::endgroup::
[2024-07-01T11:06:16.755-0400] {logging_mixin.py:188} INFO - Scraping movie details running successfully
[2024-07-01T11:06:16.757-0400] {taskinstance.py:441} INFO - ::group::Post task execution logs
[2024-07-01T11:06:16.762-0400] {taskinstance.py:2905} ERROR - Task failed with exception
Traceback (most recent call last):
  File "/home/walter/Documentos/rakuntentv/airflow/dags/movie_recommend.py", line 60, in execute_post_details_fasapi
    consumer = Consumer(consumer_config)
               ^^^^^^^^^^^^^^^^^^^^^^^^^
cimpl.KafkaException: KafkaError{code=_INVALID_ARG,val=-186,str="No such configuration property: "boostrap.servers""}

During handling of the above exception, another exception occurred:

Traceback (most recent call last):
  File "/home/walter/Documentos/rakuntentv/venv/lib/python3.12/site-packages/airflow/models/taskinstance.py", line 465, in _execute_task
    result = _execute_callable(context=context, **execute_callable_kwargs)
             ^^^^^^^^^^^^^^^^^^^^^^^^^^^^^^^^^^^^^^^^^^^^^^^^^^^^^^^^^^^^^
  File "/home/walter/Documentos/rakuntentv/venv/lib/python3.12/site-packages/airflow/models/taskinstance.py", line 432, in _execute_callable
    return execute_callable(context=context, **execute_callable_kwargs)
           ^^^^^^^^^^^^^^^^^^^^^^^^^^^^^^^^^^^^^^^^^^^^^^^^^^^^^^^^^^^^
  File "/home/walter/Documentos/rakuntentv/venv/lib/python3.12/site-packages/airflow/models/baseoperator.py", line 401, in wrapper
    return func(self, *args, **kwargs)
           ^^^^^^^^^^^^^^^^^^^^^^^^^^^
  File "/home/walter/Documentos/rakuntentv/venv/lib/python3.12/site-packages/airflow/operators/python.py", line 235, in execute
    return_value = self.execute_callable()
                   ^^^^^^^^^^^^^^^^^^^^^^^
  File "/home/walter/Documentos/rakuntentv/venv/lib/python3.12/site-packages/airflow/operators/python.py", line 252, in execute_callable
    return self.python_callable(*self.op_args, **self.op_kwargs)
           ^^^^^^^^^^^^^^^^^^^^^^^^^^^^^^^^^^^^^^^^^^^^^^^^^^^^^
  File "/home/walter/Documentos/rakuntentv/airflow/dags/movie_recommend.py", line 82, in execute_post_details_fasapi
    consumer.close()
    ^^^^^^^^
UnboundLocalError: cannot access local variable 'consumer' where it is not associated with a value
[2024-07-01T11:06:16.770-0400] {taskinstance.py:1206} INFO - Marking task as FAILED. dag_id=api_cuevana3_movie, task_id=execute_post_details_fasapi, run_id=scheduled__2024-07-01T02:00:00+00:00, execution_date=20240701T020000, start_date=20240701T150616, end_date=20240701T150616
[2024-07-01T11:06:16.797-0400] {standard_task_runner.py:110} ERROR - Failed to execute job 653 for task execute_post_details_fasapi (cannot access local variable 'consumer' where it is not associated with a value; 381778)
[2024-07-01T11:06:16.837-0400] {local_task_job_runner.py:240} INFO - Task exited with return code 1
[2024-07-01T11:06:16.859-0400] {taskinstance.py:3503} INFO - 0 downstream tasks scheduled from follow-on schedule check
[2024-07-01T11:06:16.890-0400] {local_task_job_runner.py:222} INFO - ::endgroup::
[2024-07-01T21:24:48.519-0400] {local_task_job_runner.py:120} INFO - ::group::Pre task execution logs
[2024-07-01T21:24:48.553-0400] {taskinstance.py:2076} INFO - Dependencies all met for dep_context=non-requeueable deps ti=<TaskInstance: api_cuevana3_movie.execute_post_details_fasapi scheduled__2024-07-01T02:00:00+00:00 [queued]>
[2024-07-01T21:24:48.558-0400] {taskinstance.py:2076} INFO - Dependencies all met for dep_context=requeueable deps ti=<TaskInstance: api_cuevana3_movie.execute_post_details_fasapi scheduled__2024-07-01T02:00:00+00:00 [queued]>
[2024-07-01T21:24:48.559-0400] {taskinstance.py:2306} INFO - Starting attempt 1 of 1
[2024-07-01T21:24:48.599-0400] {taskinstance.py:2330} INFO - Executing <Task(PythonOperator): execute_post_details_fasapi> on 2024-07-01 02:00:00+00:00
[2024-07-01T21:24:48.608-0400] {standard_task_runner.py:63} INFO - Started process 430806 to run task
[2024-07-01T21:24:48.612-0400] {standard_task_runner.py:90} INFO - Running: ['airflow', 'tasks', 'run', 'api_cuevana3_movie', 'execute_post_details_fasapi', 'scheduled__2024-07-01T02:00:00+00:00', '--job-id', '782', '--raw', '--subdir', 'DAGS_FOLDER/movie_recommend.py', '--cfg-path', '/tmp/tmp0vp3m91y']
[2024-07-01T21:24:48.613-0400] {standard_task_runner.py:91} INFO - Job 782: Subtask execute_post_details_fasapi
[2024-07-01T21:24:48.682-0400] {task_command.py:426} INFO - Running <TaskInstance: api_cuevana3_movie.execute_post_details_fasapi scheduled__2024-07-01T02:00:00+00:00 [running]> on host walter-VirtualBox
[2024-07-01T21:24:48.790-0400] {taskinstance.py:2648} INFO - Exporting env vars: AIRFLOW_CTX_DAG_OWNER='airflow' AIRFLOW_CTX_DAG_ID='api_cuevana3_movie' AIRFLOW_CTX_TASK_ID='execute_post_details_fasapi' AIRFLOW_CTX_EXECUTION_DATE='2024-07-01T02:00:00+00:00' AIRFLOW_CTX_TRY_NUMBER='1' AIRFLOW_CTX_DAG_RUN_ID='scheduled__2024-07-01T02:00:00+00:00'
[2024-07-01T21:24:48.791-0400] {taskinstance.py:430} INFO - ::endgroup::
[2024-07-01T21:25:07.405-0400] {taskinstance.py:441} INFO - ::group::Post task execution logs
[2024-07-01T21:25:07.414-0400] {taskinstance.py:2905} ERROR - Task failed with exception
Traceback (most recent call last):
  File "/home/walter/Documentos/rakuntentv/venv/lib/python3.12/site-packages/urllib3/connectionpool.py", line 789, in urlopen
    response = self._make_request(
               ^^^^^^^^^^^^^^^^^^^
  File "/home/walter/Documentos/rakuntentv/venv/lib/python3.12/site-packages/urllib3/connectionpool.py", line 536, in _make_request
    response = conn.getresponse()
               ^^^^^^^^^^^^^^^^^^
  File "/home/walter/Documentos/rakuntentv/venv/lib/python3.12/site-packages/urllib3/connection.py", line 464, in getresponse
    httplib_response = super().getresponse()
                       ^^^^^^^^^^^^^^^^^^^^^
  File "/usr/lib/python3.12/http/client.py", line 1428, in getresponse
    response.begin()
  File "/usr/lib/python3.12/http/client.py", line 331, in begin
    version, status, reason = self._read_status()
                              ^^^^^^^^^^^^^^^^^^^
  File "/usr/lib/python3.12/http/client.py", line 300, in _read_status
    raise RemoteDisconnected("Remote end closed connection without"
http.client.RemoteDisconnected: Remote end closed connection without response

During handling of the above exception, another exception occurred:

Traceback (most recent call last):
  File "/home/walter/Documentos/rakuntentv/venv/lib/python3.12/site-packages/requests/adapters.py", line 667, in send
    resp = conn.urlopen(
           ^^^^^^^^^^^^^
  File "/home/walter/Documentos/rakuntentv/venv/lib/python3.12/site-packages/urllib3/connectionpool.py", line 843, in urlopen
    retries = retries.increment(
              ^^^^^^^^^^^^^^^^^^
  File "/home/walter/Documentos/rakuntentv/venv/lib/python3.12/site-packages/urllib3/util/retry.py", line 474, in increment
    raise reraise(type(error), error, _stacktrace)
          ^^^^^^^^^^^^^^^^^^^^^^^^^^^^^^^^^^^^^^^^
  File "/home/walter/Documentos/rakuntentv/venv/lib/python3.12/site-packages/urllib3/util/util.py", line 38, in reraise
    raise value.with_traceback(tb)
  File "/home/walter/Documentos/rakuntentv/venv/lib/python3.12/site-packages/urllib3/connectionpool.py", line 789, in urlopen
    response = self._make_request(
               ^^^^^^^^^^^^^^^^^^^
  File "/home/walter/Documentos/rakuntentv/venv/lib/python3.12/site-packages/urllib3/connectionpool.py", line 536, in _make_request
    response = conn.getresponse()
               ^^^^^^^^^^^^^^^^^^
  File "/home/walter/Documentos/rakuntentv/venv/lib/python3.12/site-packages/urllib3/connection.py", line 464, in getresponse
    httplib_response = super().getresponse()
                       ^^^^^^^^^^^^^^^^^^^^^
  File "/usr/lib/python3.12/http/client.py", line 1428, in getresponse
    response.begin()
  File "/usr/lib/python3.12/http/client.py", line 331, in begin
    version, status, reason = self._read_status()
                              ^^^^^^^^^^^^^^^^^^^
  File "/usr/lib/python3.12/http/client.py", line 300, in _read_status
    raise RemoteDisconnected("Remote end closed connection without"
urllib3.exceptions.ProtocolError: ('Connection aborted.', RemoteDisconnected('Remote end closed connection without response'))

During handling of the above exception, another exception occurred:

Traceback (most recent call last):
  File "/home/walter/Documentos/rakuntentv/venv/lib/python3.12/site-packages/airflow/models/taskinstance.py", line 465, in _execute_task
    result = _execute_callable(context=context, **execute_callable_kwargs)
             ^^^^^^^^^^^^^^^^^^^^^^^^^^^^^^^^^^^^^^^^^^^^^^^^^^^^^^^^^^^^^
  File "/home/walter/Documentos/rakuntentv/venv/lib/python3.12/site-packages/airflow/models/taskinstance.py", line 432, in _execute_callable
    return execute_callable(context=context, **execute_callable_kwargs)
           ^^^^^^^^^^^^^^^^^^^^^^^^^^^^^^^^^^^^^^^^^^^^^^^^^^^^^^^^^^^^
  File "/home/walter/Documentos/rakuntentv/venv/lib/python3.12/site-packages/airflow/models/baseoperator.py", line 401, in wrapper
    return func(self, *args, **kwargs)
           ^^^^^^^^^^^^^^^^^^^^^^^^^^^
  File "/home/walter/Documentos/rakuntentv/venv/lib/python3.12/site-packages/airflow/operators/python.py", line 235, in execute
    return_value = self.execute_callable()
                   ^^^^^^^^^^^^^^^^^^^^^^^
  File "/home/walter/Documentos/rakuntentv/venv/lib/python3.12/site-packages/airflow/operators/python.py", line 252, in execute_callable
    return self.python_callable(*self.op_args, **self.op_kwargs)
           ^^^^^^^^^^^^^^^^^^^^^^^^^^^^^^^^^^^^^^^^^^^^^^^^^^^^^
  File "/home/walter/Documentos/rakuntentv/airflow/dags/movie_recommend.py", line 60, in execute_post_details_fasapi
    response = requests.post(api_url)
               ^^^^^^^^^^^^^^^^^^^^^^
  File "/home/walter/Documentos/rakuntentv/venv/lib/python3.12/site-packages/requests/api.py", line 115, in post
    return request("post", url, data=data, json=json, **kwargs)
           ^^^^^^^^^^^^^^^^^^^^^^^^^^^^^^^^^^^^^^^^^^^^^^^^^^^^
  File "/home/walter/Documentos/rakuntentv/venv/lib/python3.12/site-packages/requests/api.py", line 59, in request
    return session.request(method=method, url=url, **kwargs)
           ^^^^^^^^^^^^^^^^^^^^^^^^^^^^^^^^^^^^^^^^^^^^^^^^^
  File "/home/walter/Documentos/rakuntentv/venv/lib/python3.12/site-packages/requests/sessions.py", line 589, in request
    resp = self.send(prep, **send_kwargs)
           ^^^^^^^^^^^^^^^^^^^^^^^^^^^^^^
  File "/home/walter/Documentos/rakuntentv/venv/lib/python3.12/site-packages/requests/sessions.py", line 703, in send
    r = adapter.send(request, **kwargs)
        ^^^^^^^^^^^^^^^^^^^^^^^^^^^^^^^
  File "/home/walter/Documentos/rakuntentv/venv/lib/python3.12/site-packages/requests/adapters.py", line 682, in send
    raise ConnectionError(err, request=request)
requests.exceptions.ConnectionError: ('Connection aborted.', RemoteDisconnected('Remote end closed connection without response'))
[2024-07-01T21:25:07.438-0400] {taskinstance.py:1206} INFO - Marking task as FAILED. dag_id=api_cuevana3_movie, task_id=execute_post_details_fasapi, run_id=scheduled__2024-07-01T02:00:00+00:00, execution_date=20240701T020000, start_date=20240702T012448, end_date=20240702T012507
[2024-07-01T21:25:07.483-0400] {standard_task_runner.py:110} ERROR - Failed to execute job 782 for task execute_post_details_fasapi (('Connection aborted.', RemoteDisconnected('Remote end closed connection without response')); 430806)
[2024-07-01T21:25:07.540-0400] {local_task_job_runner.py:240} INFO - Task exited with return code 1
[2024-07-01T21:25:07.581-0400] {taskinstance.py:3503} INFO - 0 downstream tasks scheduled from follow-on schedule check
[2024-07-01T21:25:07.603-0400] {local_task_job_runner.py:222} INFO - ::endgroup::
[2024-07-01T23:02:09.766-0400] {local_task_job_runner.py:120} INFO - ::group::Pre task execution logs
[2024-07-01T23:02:09.781-0400] {taskinstance.py:2076} INFO - Dependencies all met for dep_context=non-requeueable deps ti=<TaskInstance: api_cuevana3_movie.execute_post_details_fasapi scheduled__2024-07-01T02:00:00+00:00 [queued]>
[2024-07-01T23:02:09.786-0400] {taskinstance.py:2076} INFO - Dependencies all met for dep_context=requeueable deps ti=<TaskInstance: api_cuevana3_movie.execute_post_details_fasapi scheduled__2024-07-01T02:00:00+00:00 [queued]>
[2024-07-01T23:02:09.786-0400] {taskinstance.py:2306} INFO - Starting attempt 1 of 1
[2024-07-01T23:02:09.808-0400] {taskinstance.py:2330} INFO - Executing <Task(PythonOperator): execute_post_details_fasapi> on 2024-07-01 02:00:00+00:00
[2024-07-01T23:02:09.815-0400] {standard_task_runner.py:63} INFO - Started process 444216 to run task
[2024-07-01T23:02:09.819-0400] {standard_task_runner.py:90} INFO - Running: ['airflow', 'tasks', 'run', 'api_cuevana3_movie', 'execute_post_details_fasapi', 'scheduled__2024-07-01T02:00:00+00:00', '--job-id', '812', '--raw', '--subdir', 'DAGS_FOLDER/movie_recommend.py', '--cfg-path', '/tmp/tmpmm6ncm1_']
[2024-07-01T23:02:09.820-0400] {standard_task_runner.py:91} INFO - Job 812: Subtask execute_post_details_fasapi
[2024-07-01T23:02:09.877-0400] {task_command.py:426} INFO - Running <TaskInstance: api_cuevana3_movie.execute_post_details_fasapi scheduled__2024-07-01T02:00:00+00:00 [running]> on host walter-VirtualBox
[2024-07-01T23:02:10.023-0400] {taskinstance.py:2648} INFO - Exporting env vars: AIRFLOW_CTX_DAG_OWNER='airflow' AIRFLOW_CTX_DAG_ID='api_cuevana3_movie' AIRFLOW_CTX_TASK_ID='execute_post_details_fasapi' AIRFLOW_CTX_EXECUTION_DATE='2024-07-01T02:00:00+00:00' AIRFLOW_CTX_TRY_NUMBER='1' AIRFLOW_CTX_DAG_RUN_ID='scheduled__2024-07-01T02:00:00+00:00'
[2024-07-01T23:02:10.026-0400] {taskinstance.py:430} INFO - ::endgroup::
[2024-07-01T23:03:01.055-0400] {logging_mixin.py:188} INFO - Scraping movie details running successfully
[2024-07-01T23:03:01.097-0400] {logging_mixin.py:188} INFO - {"image_url": "https://i0.wp.com/www.themoviedb.org/t/p/w185/6BcxgP05jDip4Zjh2P5Be2aNi0Z.jpg", "title": "Gru 4. Mi villano favorito", "rating": 8.6, "duration": "1h 35m", "year": "2024", "quality": "HD", "description": "Ver gru 4. mi villano favorito Cuevana3.Gru, Lucy y las ni\u00f1as -Margo, Edith y Agnes- dan la bienvenida a un nuevo miembro en la familia: Gru Junior, que parece llegar con el prop\u00f3sito de ser un suplicio para su padre. Gru tendr\u00e1 que enfrentarse en esta ocasi\u00f3n a su nueva n\u00e9mesis Maxime Le Mal y su sofisticada y mal\u00e9vola novia Valentina, lo que obligar\u00e1 a la familia a tener que darse a la fuga. Cuarta entrega de 'Gru, mi villano favorito'.", "genre": ["Animaci\u00f3n", "Familia", "Comedia", "Acci\u00f3n"], "country": "United States", "director": "Chris Renaud", "actors": ["Steve Carell,", "Kristen Wiig,", "Will Ferrell,", "Sof\u00eda Vergara,", "Joey King,", "Stephen Colbert,", "Chloe Fineman,", "Miranda Cosgrove,", "Dana Gaier,", "Madison Polan,", "Pierre Coffin,", "Steve Coogan,", "Chris Renaud,", "Jason Segel,", "Benjamin Bratt,", "Trey Parker,", "Sandra Bullock,", "Jon Hamm,", "Taraji P. Henson,", "Russell Brand,"], "views": 65}
[2024-07-01T23:03:01.116-0400] {python.py:237} INFO - Done. Returned value was: {"image_url": "https://i0.wp.com/www.themoviedb.org/t/p/w185/6BcxgP05jDip4Zjh2P5Be2aNi0Z.jpg", "title": "Gru 4. Mi villano favorito", "rating": 8.6, "duration": "1h 35m", "year": "2024", "quality": "HD", "description": "Ver gru 4. mi villano favorito Cuevana3.Gru, Lucy y las ni\u00f1as -Margo, Edith y Agnes- dan la bienvenida a un nuevo miembro en la familia: Gru Junior, que parece llegar con el prop\u00f3sito de ser un suplicio para su padre. Gru tendr\u00e1 que enfrentarse en esta ocasi\u00f3n a su nueva n\u00e9mesis Maxime Le Mal y su sofisticada y mal\u00e9vola novia Valentina, lo que obligar\u00e1 a la familia a tener que darse a la fuga. Cuarta entrega de 'Gru, mi villano favorito'.", "genre": ["Animaci\u00f3n", "Familia", "Comedia", "Acci\u00f3n"], "country": "United States", "director": "Chris Renaud", "actors": ["Steve Carell,", "Kristen Wiig,", "Will Ferrell,", "Sof\u00eda Vergara,", "Joey King,", "Stephen Colbert,", "Chloe Fineman,", "Miranda Cosgrove,", "Dana Gaier,", "Madison Polan,", "Pierre Coffin,", "Steve Coogan,", "Chris Renaud,", "Jason Segel,", "Benjamin Bratt,", "Trey Parker,", "Sandra Bullock,", "Jon Hamm,", "Taraji P. Henson,", "Russell Brand,"], "views": 65}
[2024-07-01T23:03:01.117-0400] {taskinstance.py:441} INFO - ::group::Post task execution logs
[2024-07-01T23:03:01.138-0400] {taskinstance.py:1206} INFO - Marking task as SUCCESS. dag_id=api_cuevana3_movie, task_id=execute_post_details_fasapi, run_id=scheduled__2024-07-01T02:00:00+00:00, execution_date=20240701T020000, start_date=20240702T030209, end_date=20240702T030301
[2024-07-01T23:03:01.207-0400] {local_task_job_runner.py:240} INFO - Task exited with return code 0
[2024-07-01T23:03:01.241-0400] {taskinstance.py:3503} INFO - 0 downstream tasks scheduled from follow-on schedule check
[2024-07-01T23:03:01.242-0400] {local_task_job_runner.py:222} INFO - ::endgroup::
[2024-07-01T23:33:47.366-0400] {local_task_job_runner.py:120} INFO - ::group::Pre task execution logs
[2024-07-01T23:33:47.385-0400] {taskinstance.py:2076} INFO - Dependencies all met for dep_context=non-requeueable deps ti=<TaskInstance: api_cuevana3_movie.execute_post_details_fasapi scheduled__2024-07-01T02:00:00+00:00 [queued]>
[2024-07-01T23:33:47.391-0400] {taskinstance.py:2076} INFO - Dependencies all met for dep_context=requeueable deps ti=<TaskInstance: api_cuevana3_movie.execute_post_details_fasapi scheduled__2024-07-01T02:00:00+00:00 [queued]>
[2024-07-01T23:33:47.391-0400] {taskinstance.py:2306} INFO - Starting attempt 1 of 1
[2024-07-01T23:33:47.412-0400] {taskinstance.py:2330} INFO - Executing <Task(PythonOperator): execute_post_details_fasapi> on 2024-07-01 02:00:00+00:00
[2024-07-01T23:33:47.419-0400] {standard_task_runner.py:63} INFO - Started process 458460 to run task
[2024-07-01T23:33:47.422-0400] {standard_task_runner.py:90} INFO - Running: ['airflow', 'tasks', 'run', 'api_cuevana3_movie', 'execute_post_details_fasapi', 'scheduled__2024-07-01T02:00:00+00:00', '--job-id', '898', '--raw', '--subdir', 'DAGS_FOLDER/movie_recommend.py', '--cfg-path', '/tmp/tmpqeqb4z63']
[2024-07-01T23:33:47.424-0400] {standard_task_runner.py:91} INFO - Job 898: Subtask execute_post_details_fasapi
[2024-07-01T23:33:47.492-0400] {task_command.py:426} INFO - Running <TaskInstance: api_cuevana3_movie.execute_post_details_fasapi scheduled__2024-07-01T02:00:00+00:00 [running]> on host walter-VirtualBox
[2024-07-01T23:33:47.692-0400] {taskinstance.py:2648} INFO - Exporting env vars: AIRFLOW_CTX_DAG_OWNER='airflow' AIRFLOW_CTX_DAG_ID='api_cuevana3_movie' AIRFLOW_CTX_TASK_ID='execute_post_details_fasapi' AIRFLOW_CTX_EXECUTION_DATE='2024-07-01T02:00:00+00:00' AIRFLOW_CTX_TRY_NUMBER='1' AIRFLOW_CTX_DAG_RUN_ID='scheduled__2024-07-01T02:00:00+00:00'
[2024-07-01T23:33:47.694-0400] {taskinstance.py:430} INFO - ::endgroup::
[2024-07-01T23:34:42.001-0400] {logging_mixin.py:188} INFO - Scraping movie details running successfully
[2024-07-01T23:34:42.034-0400] {logging_mixin.py:188} INFO - {"image_url": "https://i0.wp.com/www.themoviedb.org/t/p/w185/6BcxgP05jDip4Zjh2P5Be2aNi0Z.jpg", "title": "Gru 4. Mi villano favorito", "rating": 8.6, "duration": "1h 35m", "year": "2024", "quality": "HD", "description": "Ver gru 4. mi villano favorito Cuevana3.Gru, Lucy y las ni\u00f1as -Margo, Edith y Agnes- dan la bienvenida a un nuevo miembro en la familia: Gru Junior, que parece llegar con el prop\u00f3sito de ser un suplicio para su padre. Gru tendr\u00e1 que enfrentarse en esta ocasi\u00f3n a su nueva n\u00e9mesis Maxime Le Mal y su sofisticada y mal\u00e9vola novia Valentina, lo que obligar\u00e1 a la familia a tener que darse a la fuga. Cuarta entrega de 'Gru, mi villano favorito'.", "genre": ["Animaci\u00f3n", "Familia", "Comedia", "Acci\u00f3n"], "country": "United States", "director": "Chris Renaud", "actors": ["Steve Carell,", "Kristen Wiig,", "Will Ferrell,", "Sof\u00eda Vergara,", "Joey King,", "Stephen Colbert,", "Chloe Fineman,", "Miranda Cosgrove,", "Dana Gaier,", "Madison Polan,", "Pierre Coffin,", "Steve Coogan,", "Chris Renaud,", "Jason Segel,", "Benjamin Bratt,", "Trey Parker,", "Sandra Bullock,", "Jon Hamm,", "Taraji P. Henson,", "Russell Brand,"], "views": 65}
[2024-07-01T23:34:42.045-0400] {python.py:237} INFO - Done. Returned value was: {"image_url": "https://i0.wp.com/www.themoviedb.org/t/p/w185/6BcxgP05jDip4Zjh2P5Be2aNi0Z.jpg", "title": "Gru 4. Mi villano favorito", "rating": 8.6, "duration": "1h 35m", "year": "2024", "quality": "HD", "description": "Ver gru 4. mi villano favorito Cuevana3.Gru, Lucy y las ni\u00f1as -Margo, Edith y Agnes- dan la bienvenida a un nuevo miembro en la familia: Gru Junior, que parece llegar con el prop\u00f3sito de ser un suplicio para su padre. Gru tendr\u00e1 que enfrentarse en esta ocasi\u00f3n a su nueva n\u00e9mesis Maxime Le Mal y su sofisticada y mal\u00e9vola novia Valentina, lo que obligar\u00e1 a la familia a tener que darse a la fuga. Cuarta entrega de 'Gru, mi villano favorito'.", "genre": ["Animaci\u00f3n", "Familia", "Comedia", "Acci\u00f3n"], "country": "United States", "director": "Chris Renaud", "actors": ["Steve Carell,", "Kristen Wiig,", "Will Ferrell,", "Sof\u00eda Vergara,", "Joey King,", "Stephen Colbert,", "Chloe Fineman,", "Miranda Cosgrove,", "Dana Gaier,", "Madison Polan,", "Pierre Coffin,", "Steve Coogan,", "Chris Renaud,", "Jason Segel,", "Benjamin Bratt,", "Trey Parker,", "Sandra Bullock,", "Jon Hamm,", "Taraji P. Henson,", "Russell Brand,"], "views": 65}
[2024-07-01T23:34:42.046-0400] {taskinstance.py:441} INFO - ::group::Post task execution logs
[2024-07-01T23:34:42.077-0400] {taskinstance.py:1206} INFO - Marking task as SUCCESS. dag_id=api_cuevana3_movie, task_id=execute_post_details_fasapi, run_id=scheduled__2024-07-01T02:00:00+00:00, execution_date=20240701T020000, start_date=20240702T033347, end_date=20240702T033442
[2024-07-01T23:34:42.160-0400] {local_task_job_runner.py:240} INFO - Task exited with return code 0
[2024-07-01T23:34:42.258-0400] {taskinstance.py:3503} INFO - 1 downstream tasks scheduled from follow-on schedule check
[2024-07-01T23:34:42.276-0400] {local_task_job_runner.py:222} INFO - ::endgroup::
